Workbook

Sheet Prices
A1: Date | B1: Vestas | C1: Ørsted | D1: Fortum | E1: Neste | F1: Nibe | G1: Engie | H1: Centrica | I1: SSE | J1: EDP | K1: RWE | L1: Iberdrola | M1: Enel
A2: 42736 | B2: 12.951178 | C2: 19.48288 | D2: 14.79 | E2: 10.753322 | F2: 1.9093267 | G2: 11.065 | H2: 2.6111948 | I2: 17.334236 | J2: 2.627098 | K2: 12.255 | L2: 5.834 | M2: 3.864
A3: 42767 | B3: 14.005326 | C3: 19.314621 | D3: 14.49 | E3: 10.959989 | F3: 1.8965434 | G3: 11.54 | H3: 2.6572027 | I3: 18.046494 | J3: 2.8528645 | K3: 13.455 | L3: 6.274 | M3: 4.052
A4: 42795 | B4: 15.249492 | C4: 20.097979 | D4: 14.83 | E4: 12.186654 | F4: 1.8757993 | G4: 13.28 | H4: 2.5370264 | I4: 17.256454 | J4: 3.103064 | K4: 15.535 | L4: 6.705 | M4: 4.414
A5: 42826 | B5: 15.812166 | C5: 20.102758 | D5: 13.36 | E5: 12.496654 | F5: 2.0352745 | G5: 12.95 | H5: 2.3511927 | I5: 16.52607 | J5: 2.9613492 | K5: 15.205 | L5: 6.602 | M5: 4.364
A6: 42856 | B6: 15.820786 | C6: 21.598272 | D6: 14.18 | E6: 11.796654 | F6: 2.0796947 | G6: 13.585 | H6: 2.3339274 | I6: 17.277721 | J6: 3.199821 | K6: 18.08 | L6: 7.098 | M6: 4.758
A7: 42887 | B7: 16.166742 | C7: 21.970346 | D7: 13.73 | E7: 11.496655 | F7: 2.067302 | G7: 13.215 | H7: 2.2800386 | I7: 16.547932 | J7: 2.798133 | K7: 17.445 | L7: 6.933 | M7: 4.6940002
A8: 42917 | B8: 16.51266 | C8: 22.637955 | D8: 13.82 | E8: 12.209988 | F8: 2.0197673 | G8: 13.605 | H8: 2.2196138 | I8: 15.419887 | J8: 2.932029 | K8: 17.815 | L8: 6.664 | M8: 4.824
A9: 42948 | B9: 15.300431 | C9: 24.3014 | D9: 15.08 | E9: 12.346654 | F9: 1.9330388 | G9: 14.02 | H9: 2.1665502 | I9: 15.444392 | J9: 3.151931 | K9: 20.955 | L9: 6.861 | M9: 5.085
A10: 42979 | B10: 15.184677 | C10: 26.917282 | D10: 16.89 | E10: 12.316654 | F10: 2.1257515 | G10: 14.37 | H10: 2.1222174 | I10: 15.854213 | J10: 3.1128376 | K10: 19.22 | L10: 6.572 | M10: 5.095
A11: 43009 | B11: 15.145337 | C11: 26.739748 | D11: 18.23 | E11: 15.943317 | F11: 2.146835 | G11: 14.51 | H11: 1.9355845 | I11: 15.753697 | J11: 2.9936016 | K11: 21.46 | L11: 6.938 | M11: 5.325
A12: 43040 | B12: 10.754753 | C12: 27.169106 | D12: 17.68 | E12: 17.399982 | F12: 2.0076513 | G12: 14.705 | H12: 1.6416135 | I12: 15.54197 | J12: 2.8782752 | K12: 19.25 | L12: 6.672 | M12: 5.455
A13: 43070 | B13: 11.518459 | C13: 25.283905 | D13: 16.5 | E13: 17.783314 | F13: 1.9986675 | G13: 14.335 | H13: 1.5467404 | I13: 14.870337 | J13: 2.8196347 | K13: 17 | L13: 6.46 | M13: 5.13
... A111: 46054 | B111: 21.742708 | C111: 20.07637 | D111: 19.81 | E111: 21.18 | F111: 3.4797761 | G111: 28.93 | H111: 2.267699 | I111: 30.619345 | J111: 4.516 | K111: 54.54 | L111: 20.05 | M111: 10.194

Sheet Target_Prices
A1: Date | B1: Vestas | C1: Ørsted | D1: Fortum | E1: Neste | F1: Nibe | G1: Engie | H1: Centrica | I1: SSE | J1: EDP | K1: RWE | L1: Iberdrola | M1: Enel
A2: 42734 | B2: 14.8282 | C2: 19.6644 | D2: 13.6167 | E2: 12.4637 | F2: 1.90462 | G2: 15.1643 | H2: 2.78976 | I2: 18.7059 | J2: 3.15464 | K2: 13.4582 | L2: 6.66279 | M2: 4.65977
A3: 42825 | B3: 16.124 | C3: 20.8855 | D3: 13.4034 | E3: 11.2683 | F3: 1.94314 | G3: 14.4553 | H3: 2.60594 | I3: 18.5509 | J3: 3.17217 | K3: 14.6578 | L3: 6.80245 | M3: 4.66958
A4: 42916 | B4: 16.7821 | C4: 21.898 | D4: 13.475 | E4: 11.5789 | F4: 2.20316 | G4: 14.5333 | H4: 2.36191 | I4: 17.664 | J4: 3.16519 | K4: 18.7515 | L4: 7.2241 | M4: 5.0125
A5: 43008 | B5: 17.2493 | C5: 25.1915 | D5: 14.7889 | E5: 11.8066 | F5: 2.06524 | G5: 14.9294 | H5: 2.3499 | I5: 17.4692 | J5: 3.13315 | K5: 20.4691 | L5: 7.23554 | M5: 5.3004
A6: 43099 | B6: 13.4604 | C6: 26.8532 | D6: 17.5795 | E6: 15.2877 | F6: 1.97917 | G6: 16.03 | H6: 1.78053 | I6: 17.1952 | J6: 3.01377 | K6: 20.4491 | L6: 7.18565 | M6: 5.7948
A7: 43190 | B7: 13.6235 | C7: 28.053 | D7: 18.1152 | E7: 17.8916 | F7: 1.9515 | G7: 15.3375 | H7: 1.76227 | I7: 16.6775 | J7: 2.91203 | K7: 21.086 | L7: 7.05926 | M7: 5.7716
A8: 43281 | B8: 13.5371 | C8: 30.3469 | D8: 19.375 | E8: 20.6648 | F8: 2.11427 | G8: 15.5524 | H8: 1.76403 | I8: 16.3625 | J8: 3.25064 | K8: 22.5652 | L8: 7.1779 | M8: 5.65
A9: 43373 | B9: 13.0754 | C9: 31.5502 | D9: 21.35 | E9: 22.7543 | F9: 2.27159 | G9: 15.5864 | H9: 1.80693 | I9: 15.1594 | J9: 3.32929 | K9: 24.685 | L9: 7.27959 | M9: 5.5216
A10: 43464 | B10: 13.464 | C10: 34.8581 | D10: 20.2333 | E10: 25.3122 | F10: 2.31923 | G10: 15.3083 | H10: 1.72613 | I10: 14.8309 | J10: 3.3197 | K10: 22.3967 | L10: 7.40269 | M10: 5.51818
A11: 43555 | B11: 14.9349 | C11: 37.2781 | D11: 21.1184 | E11: 30.6583 | F11: 2.59247 | G11: 15.5813 | H11: 1.51488 | I11: 15.0581 | J11: 3.48685 | K11: 24.0925 | L11: 7.79042 | M11: 5.8505
A12: 43646 | B12: 16.3166 | C12: 39.7116 | D12: 20.8972 | E12: 34.2485 | F12: 2.75141 | G12: 15.5857 | H12: 1.14384 | I12: 13.7239 | J12: 3.57036 | K12: 25.4974 | L12: 8.55923 | M12: 6.22947
A13: 43738 | B13: 16.3752 | C13: 47.5149 | D13: 21.85 | E13: 34.0737 | F13: 2.73213 | G13: 15.9937 | H13: 0.877397 | I13: 14.3221 | J13: 3.82569 | K13: 28.2143 | L13: 9.10157 | M13: 6.83
... A38: 46021 | B38: 22.1403 | C38: 18.2971 | D38: 15.7429 | E38: 20.4727 | F38: 3.9991 | G38: 24.3235 | H38: 2.22805 | I38: 28.206 | J38: 4.54 | K38: 49.7368 | L38: 17.9048 | M38: 9.305

Sheet MSCI_EU
A1: DATE | B1: MSCI EU
A2: 42398 | B2: 115.37109
A3: 42429 | B3: 112.49869
A4: 42460 | B4: 113.62127
A5: 42489 | B5: 115.14508
A6: 42521 | B6: 116.85846
A7: 42551 | B7: 111.62442
A8: 42580 | B8: 115.45176
A9: 42613 | B9: 115.92785
A10: 42643 | B10: 115.81896
A11: 42674 | B11: 114.74591
A12: 42704 | B12: 115.79812
A13: 42734 | B13: 122.49678
... A123: 46080 | B123: 211.7

Sheet Master_data
A1: DATE | B1: firm | C1: price | D1: Target_price | E1: Return | F1: Signal
A2: 42766 | B2: Vestas | C2: 12.951178 | D2: =LOOKUP(EOMONTH(A2,0),Target_Prices!A$2:A$38,Target_Prices!B$2:B$38) -> 14.8282 | F2: =(D2-C2)/C2 -> 0.1449306
A3: 42794 | B3: Vestas | C3: 14.005326 | D3: =LOOKUP(EOMONTH(A3,0),Target_Prices!A$2:A$38,Target_Prices!B$2:B$38) -> 14.8282 | E3: =(C3/C2)-1 -> 0.081393986 | F3: =(D3-C3)/C3 -> 0.058754362
A4: 42825 | B4: Vestas | C4: 15.249492 | D4: =LOOKUP(EOMONTH(A4,0),Target_Prices!A$2:A$38,Target_Prices!B$2:B$38) -> 16.124 | E4: =(C4/C3)-1 -> 0.088835205 | F4: =(D4-C4)/C4 -> 0.057346697
A5: 42853 | B5: Vestas | C5: 15.812166 | D5: =LOOKUP(EOMONTH(A5,0),Target_Prices!A$2:A$38,Target_Prices!B$2:B$38) -> 16.124 | E5: =(C5/C4)-1 -> 0.036897885 | F5: =(D5-C5)/C5 -> 0.019721144
A6: 42886 | B6: Vestas | C6: 15.820786 | D6: =LOOKUP(EOMONTH(A6,0),Target_Prices!A$2:A$38,Target_Prices!B$2:B$38) -> 16.124 | E6: =(C6/C5)-1 -> 0.00054514985 | F6: =(D6-C6)/C6 -> 0.019165546
A7: 42916 | B7: Vestas | C7: 16.166742 | D7: =LOOKUP(EOMONTH(A7,0),Target_Prices!A$2:A$38,Target_Prices!B$2:B$38) -> 16.7821 | E7: =(C7/C6)-1 -> 0.021867182 | F7: =(D7-C7)/C7 -> 0.038063204
A8: 42947 | B8: Vestas | C8: 16.51266 | D8: =LOOKUP(EOMONTH(A8,0),Target_Prices!A$2:A$38,Target_Prices!B$2:B$38) -> 16.7821 | E8: =(C8/C7)-1 -> 0.02139689 | F8: =(D8-C8)/C8 -> 0.016317177
A9: 42978 | B9: Vestas | C9: 15.300431 | D9: =LOOKUP(EOMONTH(A9,0),Target_Prices!A$2:A$38,Target_Prices!B$2:B$38) -> 16.7821 | E9: =(C9/C8)-1 -> -0.073412097 | F9: =(D9-C9)/C9 -> 0.096838383
A10: 43007 | B10: Vestas | C10: 15.184677 | D10: =LOOKUP(EOMONTH(A10,0),Target_Prices!A$2:A$38,Target_Prices!B$2:B$38) -> 17.2493 | E10: =(C10/C9)-1 -> -0.0075654078 | F10: =(D10-C10)/C10 -> 0.13596753
A11: 43039 | B11: Vestas | C11: 15.145337 | D11: =LOOKUP(EOMONTH(A11,0),Target_Prices!A$2:A$38,Target_Prices!B$2:B$38) -> 17.2493 | E11: =(C11/C10)-1 -> -0.0025907696 | F11: =(D11-C11)/C11 -> 0.1389182
A12: 43069 | B12: Vestas | C12: 10.754753 | D12: =LOOKUP(EOMONTH(A12,0),Target_Prices!A$2:A$38,Target_Prices!B$2:B$38) -> 17.2493 | E12: =(C12/C11)-1 -> -0.28989675 | F12: =(D12-C12)/C12 -> 0.60387691
A13: 43098 | B13: Vestas | C13: 11.518459 | D13: =LOOKUP(EOMONTH(A13,0),Target_Prices!A$2:A$38,Target_Prices!B$2:B$38) -> 13.4604 | E13: =(C13/C12)-1 -> 0.071011022 | F13: =(D13-C13)/C13 -> 0.16859382
A14: 43131 | B14: Vestas | C14: 10.991138 | D14: =LOOKUP(EOMONTH(A14,0),Target_Prices!A$2:A$38,Target_Prices!B$2:B$38) -> 13.4604 | E14: =(C14/C13)-1 -> -0.045780516 | F14: =(D14-C14)/C14 -> 0.22465936
... A111: 46080 | B111: Vestas | C111: 21.742708 | D111: =LOOKUP(EOMONTH(A111,0),Target_Prices!A$2:A$38,Target_Prices!B$2:B$38) -> 22.1403 | E111: =(C111/C110)-1 -> -0.15279203 | F111: =(D111-C111)/C111 -> 0.018286223
A112: 42766 | B112: Ørsted | C112: 19.48288 | D112: =LOOKUP(EOMONTH(A112,0),Target_Prices!A$2:A$38,Target_Prices!C$2:C$38) -> 19.6644 | F112: =(D112-C112)/C112 -> 0.0093168977
A113: 42794 | B113: Ørsted | C113: 19.314621 | D113: =LOOKUP(EOMONTH(A113,0),Target_Prices!A$2:A$38,Target_Prices!C$2:C$38) -> 19.6644 | E113: =(C113/C112)-1 -> -0.0086362489 | F113: =(D113-C113)/C113 -> 0.018109545
A114: 42825 | B114: Ørsted | C114: 20.097979 | D114: =LOOKUP(EOMONTH(A114,0),Target_Prices!A$2:A$38,Target_Prices!C$2:C$38) -> 20.8855 | E114: =(C114/C113)-1 -> 0.040557772 | F114: =(D114-C114)/C114 -> 0.039184089
A115: 42853 | B115: Ørsted | C115: 20.102758 | D115: =LOOKUP(EOMONTH(A115,0),Target_Prices!A$2:A$38,Target_Prices!C$2:C$38) -> 20.8855 | E115: =(C115/C114)-1 -> 0.0002377851 | F115: =(D115-C115)/C115 -> 0.038937045
A116: 42886 | B116: Ørsted | C116: 21.598272 | D116: =LOOKUP(EOMONTH(A116,0),Target_Prices!A$2:A$38,Target_Prices!C$2:C$38) -> 20.8855 | E116: =(C116/C115)-1 -> 0.074393474 | F116: =(D116-C116)/C116 -> -0.033001344
A117: 42916 | B117: Ørsted | C117: 21.970346 | D117: =LOOKUP(EOMONTH(A117,0),Target_Prices!A$2:A$38,Target_Prices!C$2:C$38) -> 21.898 | E117: =(C117/C116)-1 -> 0.017227026 | F117: =(D117-C117)/C117 -> -0.0032928931
A118: 42947 | B118: Ørsted | C118: 22.637955 | D118: =LOOKUP(EOMONTH(A118,0),Target_Prices!A$2:A$38,Target_Prices!C$2:C$38) -> 21.898 | E118: =(C118/C117)-1 -> 0.030386822 | F118: =(D118-C118)/C118 -> -0.032686477
A119: 42978 | B119: Ørsted | C119: 24.3014 | D119: =LOOKUP(EOMONTH(A119,0),Target_Prices!A$2:A$38,Target_Prices!C$2:C$38) -> 21.898 | E119: =(C119/C118)-1 -> 0.073480356 | F119: =(D119-C119)/C119 -> -0.098899652
A120: 43007 | B120: Ørsted | C120: 26.917282 | D120: =LOOKUP(EOMONTH(A120,0),Target_Prices!A$2:A$38,Target_Prices!C$2:C$38) -> 25.1915 | E120: =(C120/C119)-1 -> 0.10764326 | F120: =(D120-C120)/C120 -> -0.064114274
A121: 43039 | B121: Ørsted | C121: 26.739748 | D121: =LOOKUP(EOMONTH(A121,0),Target_Prices!A$2:A$38,Target_Prices!C$2:C$38) -> 25.1915 | E121: =(C121/C120)-1 -> -0.0065955396 | F121: =(D121-C121)/C121 -> -0.05790062
A122: 43069 | B122: Ørsted | C122: 27.169106 | D122: =LOOKUP(EOMONTH(A122,0),Target_Prices!A$2:A$38,Target_Prices!C$2:C$38) -> 25.1915 | E122: =(C122/C121)-1 -> 0.01605692 | F122: =(D122-C122)/C122 -> -0.072788777
A123: 43098 | B123: Ørsted | C123: 25.283905 | D123: =LOOKUP(EOMONTH(A123,0),Target_Prices!A$2:A$38,Target_Prices!C$2:C$38) -> 26.8532 | E123: =(C123/C122)-1 -> -0.069387671 | F123: =(D123-C123)/C123 -> 0.062066955
A124: 43131 | B124: Ørsted | C124: 27.183792 | D124: =LOOKUP(EOMONTH(A124,0),Target_Prices!A$2:A$38,Target_Prices!C$2:C$38) -> 26.8532 | E124: =(C124/C123)-1 -> 0.075142151 | F124: =(D124-C124)/C124 -> -0.012161364
... A221: 46080 | B221: Ørsted | C221: 20.07637 | D221: =LOOKUP(EOMONTH(A221,0),Target_Prices!A$2:A$38,Target_Prices!C$2:C$38) -> 18.2971 | E221: =(C221/C220)-1 -> 0.058783387 | F221: =(D221-C221)/C221 -> -0.088625085
A222: 42766 | B222: Fortum | C222: 14.79 | D222: =LOOKUP(EOMONTH(A222,0),Target_Prices!A$2:A$38,Target_Prices!D$2:D$38) -> 13.6167 | F222: =(D222-C222)/C222 -> -0.079330629
A223: 42794 | B223: Fortum | C223: 14.49 | D223: =LOOKUP(EOMONTH(A223,0),Target_Prices!A$2:A$38,Target_Prices!D$2:D$38) -> 13.6167 | E223: =(C223/C222)-1 -> -0.020283976 | F223: =(D223-C223)/C223 -> -0.060269151
A224: 42825 | B224: Fortum | C224: 14.83 | D224: =LOOKUP(EOMONTH(A224,0),Target_Prices!A$2:A$38,Target_Prices!D$2:D$38) -> 13.4034 | E224: =(C224/C223)-1 -> 0.023464458 | F224: =(D224-C224)/C224 -> -0.096196898
A225: 42853 | B225: Fortum | C225: 13.36 | D225: =LOOKUP(EOMONTH(A225,0),Target_Prices!A$2:A$38,Target_Prices!D$2:D$38) -> 13.4034 | E225: =(C225/C224)-1 -> -0.099123399 | F225: =(D225-C225)/C225 -> 0.003248503
A226: 42886 | B226: Fortum | C226: 14.18 | D226: =LOOKUP(EOMONTH(A226,0),Target_Prices!A$2:A$38,Target_Prices!D$2:D$38) -> 13.4034 | E226: =(C226/C225)-1 -> 0.061377246 | F226: =(D226-C226)/C226 -> -0.054767278
A227: 42916 | B227: Fortum | C227: 13.73 | D227: =LOOKUP(EOMONTH(A227,0),Target_Prices!A$2:A$38,Target_Prices!D$2:D$38) -> 13.475 | E227: =(C227/C226)-1 -> -0.031734838 | F227: =(D227-C227)/C227 -> -0.018572469
A228: 42947 | B228: Fortum | C228: 13.82 | D228: =LOOKUP(EOMONTH(A228,0),Target_Prices!A$2:A$38,Target_Prices!D$2:D$38) -> 13.475 | E228: =(C228/C227)-1 -> 0.0065549891 | F228: =(D228-C228)/C228 -> -0.024963821
A229: 42978 | B229: Fortum | C229: 15.08 | D229: =LOOKUP(EOMONTH(A229,0),Target_Prices!A$2:A$38,Target_Prices!D$2:D$38) -> 13.475 | E229: =(C229/C228)-1 -> 0.091172214 | F229: =(D229-C229)/C229 -> -0.10643236
A230: 43007 | B230: Fortum | C230: 16.89 | D230: =LOOKUP(EOMONTH(A230,0),Target_Prices!A$2:A$38,Target_Prices!D$2:D$38) -> 14.7889 | E230: =(C230/C229)-1 -> 0.12002653 | F230: =(D230-C230)/C230 -> -0.12439905
A231: 43039 | B231: Fortum | C231: 18.23 | D231: =LOOKUP(EOMONTH(A231,0),Target_Prices!A$2:A$38,Target_Prices!D$2:D$38) -> 14.7889 | E231: =(C231/C230)-1 -> 0.079336886 | F231: =(D231-C231)/C231 -> -0.18876029
A232: 43069 | B232: Fortum | C232: 17.68 | D232: =LOOKUP(EOMONTH(A232,0),Target_Prices!A$2:A$38,Target_Prices!D$2:D$38) -> 14.7889 | E232: =(C232/C231)-1 -> -0.030170049 | F232: =(D232-C232)/C232 -> -0.16352376
...

Sheet FIRM CRITERIA
A1: companies | B1: tick | C1: Market cap (M) @20/02 | D1: Analyst taget history @Q1 2017 | E1: no of analyst as at date | F1: 30D Average trading volume | G1: Price @23/02 in euros (changes constantly*) | H1: Liquidity requirement @avrg daily trading value >10million euros | I1: FS consistency: public listing b4 2026|price history continous 2016|Extreme restructuring? | J1: SECTOR/Industry | K1: Exhange
A2: Vestas | B2: VWS-DK | C2: 21678.64 | D2: yes | E2: 23 | F2: 3163378 | G2: 21.18 | H2: =F2*G2 -> 67000346 | I2: YES, YES,NO | J2: Industrial manufacturing/renewable energy | K2: OMX Nordic Copenhagen
A3: Fortum | B3: FORTUM-FI | C3: 17671.62 | D3: yes | E3: 30 | F3: 1375843 | G3: 19.61 | H3: =F3*G3 -> 26980281 | I3: YES, YES,NO | J3: Utilities/International electric utilites | K3: OMX Nordic Helsinki
A4: Neste | B4: NESTE-FI | C4: 16365.59 | D4: yes | E4: 21 | F4: 1520903 | G4: 21.04 | H4: =F4*G4 -> 31999799 | I4: YES, YES, private placement in '18 | J4: Downstream and Midstream Energy/Europe petroluem refinery | K4: OMX Nordic Helsinki
A5: NIBE | B5: NIBE.B-SE | C5: 7575.8 | D5: yes | E5: 9 | F5: 9074883 | G5: 3.71 | H5: =F5*G5 -> 33667816 | I5: YES, YES, NO | J5: industrial manufacturing/Environmental Control Machinery/Equipment Products | K5: OMX Nordic Stockholm
A6: Ørsted | B6: ORSTED-DK | C6: 27430.8 | D6: yes | E6: 16 | F6: 1470664 | G6: 20.39 | H6: =F6*G6 -> 29986839 | I6: YES, YES, NO | J6: UTILITIES/EUROPE WHOLESALE POWER | K6: OMX Nordic Copenhagen
A7: Engie | B7: ENGI-FR | C7: 63952.36 | D7: yes | E7: 19 | F7: 4349721 | G7: 26.39 | H7: =F7*G7 -> 1.1478914e+08 | I7: YES, YES, NO | J7: UTILITIES/Other International Energy Utilities | K7: EURONEXT PARIS
A8: CENTRICA | B8: CAN-GB | C8: 9754.4 | D8: yes | E8: 19 | F8: 13350397 | G8: 2.2 | H8: =F8*G8 -> 29370873 | I8: YES, YES, NO | J8: UTILITIES/Other International Energy Utilities | K8: London
A9: SSE | B9: SSE-GB | C9: 35837.67 | D9: yes | E9: 18 | F9: 3402160 | G9: 29.74 | H9: =F9*G9 -> 1.0118024e+08 | I9: YES, YES, NO | J9: Utilities/International electric utilites | K9: London
A10: EDP | B10: EDP-PT | C10: 17767.29 | D10: yes | E10: 21 | F10: 13107864 | G10: 4.33 | H10: =F10*G10 -> 56757051 | I10: yes, yes, no | J10: Utilities/ Europe wholesale power | K10: Euronext Lisbon
A11: RWE | B11: RWE-DE | C11: 38560.73 | D11: yes | E11: 28 | F11: 2066534 | G11: 52.04 | H11: =F11*G11 -> 1.0754243e+08 | I11: YES, YES, planned M&A aug '26 | J11: Utilities/ Europe wholesale power | K11: Xetra
A12: Iberdrola | B12: IBE-ES | C12: 132502.15 | D12: yes | E12: 27 | F12: 9828868 | G12: 19.79 | H12: =F12*G12 -> 1.945133e+08 | I12: YES, YES, NO | J12: Utilities/ Europe wholesale power | K12: Madrid
A13: Enel | B13: ENEL-IT | C13: 92242.19 | D13: yes | E13: 24 | F13: 25093547 | G13: 9.68 | H13: =F13*G13 -> 2.4290553e+08 | I13: yes, yes, no | J13: Utilities/International electric utilites | K13: MILAN
A16: COMPANY | B16: TICKER | C16: COUNTRY | D16: SECTOR | E16: Market Capitalization (€m) | F16: No of analyst target ratings | G16: 30D Average Trading Value (€ millions) | H16: EXCHANGE | I16: ROLE IN ENERGY TRANSITION
A17: Vestas | B17: VWS-DK | C17: Denmark | D17: Renewable Energy Equipment | E17: 21678.64 | F17: 23 | G17: =E17*F17 -> 498608.72 | H17: OMX Nordic Copenhagen | I17: Builds wind turbines used to generate renewable energy
A18: Fortum | B18: FORTUM-FI | C18: Finland | D18: Integrated Utilities | E18: 17671.62 | F18: 30 | G18: =E18*F18 -> 530148.6 | H18: OMX Nordic Helsinki | I18: Produces low-carbon electricity
A19: Neste | B19: NESTE-FI | C19: Finland | D19: Renewable Fuels | E19: 16365.59 | F19: 21 | G19: =E19*F19 -> 343677.39 | H19: OMX Nordic Helsinki | I19: Produces renewable fuels to replace fossil fuels
A20: NIBE | B20: NIBE.B-SE | C20: Sweden | D20: Electrification Equipment | E20: 7575.8 | F20: 9 | G20: =E20*F20 -> 68182.2 | H20: OMX Nordic Stockholm | I20: Produces energy-efficient heating solutions (heat pumps)
A21: Ørsted | B21: ORSTED-DK | C21: Denmark | D21: Integrated Utilities | E21: 27430.8 | F21: 16 | G21: =E21*F21 -> 438892.8 | H21: OMX Nordic Copenhagen | I21: Develops and operates offshore wind farms
A22: Engie | B22: ENGI-FR | C22: France | D22: Integrated Utilities | E22: 63952.36 | F22: 19 | G22: =E22*F22 -> 1215094.8 | H22: EURONEXT PARIS | I22: Provides energy services and invest in renewables
A23: CENTRICA | B23: CAN-GB | C23: Great Britain | D23: Integrated Utilities | E23: 9754.4 | F23: 19 | G23: =E23*F23 -> 185333.6 | H23: London | I23: Supplies energy and supports low_carbon energy solutions
A24: SSE | B24: SSE-GB | C24: Great Britain | D24: Integrated Utilities | E24: 35837.67 | F24: 18 | G24: =E24*F24 -> 645078.06 | H24: London | I24: Generates electricity and invests in renewable energy
A25: EDP | B25: EDP-PT | C25: Portugal | D25: Integrated Utilities | E25: 17767.29 | F25: 21 | G25: =E25*F25 -> 373113.09 | H25: Euronext Lisbon | I25: Develops and operates wind and solar energy
A26: RWE | B26: RWE-DE | C26: Germany | D26: Integrated Utilities | E26: 38560.73 | F26: 28 | G26: =E26*F26 -> 1079700.4 | H26: Xetra | I26: Expanding into renewable energy from traditional power
A27: Iberdrola | B27: IBE-ES | C27: Spain | D27: Integrated Utilities | E27: 132502.15 | F27: 27 | G27: =E27*F27 -> 3577558 | H27: Madrid | I27: Produces and supplies renewable electricity
A28: Enel | B28: ENEL-IT | C28: Italy | D28: Integrated Utilities | E28: 92242.19 | F28: 24 | G28: =E28*F28 -> 2213812.6 | H28: MILAN | I28: Generates and distributes renewable power
A31: COMPANY | B31: COUNTRY | C31: SECTOR | D31: ROLE IN ENERGY TRANSITION
A32: Vestas | B32: Denmark | C32: Renewable Energy Equipment | D32: Builds wind turbines used to generate renewable energy
A33: Fortum | B33: Finland | C33: Integrated Utilities | D33: Produces low-carbon electricity
A34: Neste | B34: Finland | C34: Renewable Fuels | D34: Produces renewable fuels to replace fossil fuels
A35: NIBE | B35: Sweden | C35: Electrification Equipment | D35: Produces energy-efficient heating solutions (heat pumps)
A36: Ørsted | B36: Denmark | C36: Integrated Utilities | D36: Develops and operates offshore wind farms
A37: Engie | B37: France | C37: Integrated Utilities | D37: Provides energy services and invest in renewables
A38: CENTRICA | B38: Great Britain | C38: Integrated Utilities | D38: Supplies energy and supports low_carbon energy solutions
A39: SSE | B39: Great Britain | C39: Integrated Utilities | D39: Generates electricity and invests in renewable energy
A40: EDP | B40: Portugal | C40: Integrated Utilities | D40: Develops and operates wind and solar energy
A41: RWE | B41: Germany | C41: Integrated Utilities | D41: Expanding into renewable energy from traditional power
A42: Iberdrola | B42: Spain | C42: Integrated Utilities | D42: Produces and supplies renewable electricity
A43: Enel | B43: Italy | C43: Integrated Utilities | D43: Generates and distributes renewable power
