Workbook

Sheet DATA
D2: Mean-Variance Optimization
B3: Date | D3: VFF-US | E3: FENC-US | F3: BDOUY-US | G3: SPMYY-US | H3: AHCHY-US | I3: NSC-US | J3: FQVTF-US | K3: CRAI-US | L3: CHEF-US | M3: SCGPY-US | N3: KOS-US | O3: DIISY-US | P3: TSLA-US | Q3: AMZN-US | R3: AAPL-US | S3: AVGO-US | T3: F-US | U3: SMCI-US | V3: CMCSA-US | W3: HAL-US | X3: BIRDF-US | Y3: EPRT-US | Z3: OTSKY-US | AA3: OHI-US | AB3: AGYS-US | AC3: CWBK-US | AD3: SSBI-US | AE3: PLOW-US | AF3: NWN-US | AG3: MNSB-US
B4: 43496 | D4: 5.5747 | E4: 6.69 | F4: 26.51 | G4: 7.925 | H4: 27.018 | I4: 167.74 | J4: 34.3 | K4: 41.74 | L4: 32.12 | M4: 1.452 | N4: 5.13 | O4: 17.716 | P4: 20.46798 | Q4: 85.9365 | R4: 41.61 | S4: 26.825 | T4: 8.8 | U4: 1.5100001 | V4: 36.57 | W4: 31.36 | X4: 4.7501 | Y4: 15.9 | Z4: 20.459 | AA4: 40.19 | AB4: 17.7 | AC4: 19.5 | AD4: 10.705365 | AE4: 35.4 | AF4: 62.6 | AG4: 19.85
B5: 43524 | D5: 10.58 | E5: 6.65 | F5: 25.68 | G5: 8.04 | H5: 28.6 | I5: 179.3 | J5: 36.19 | K5: 49.96 | L5: 32.01 | M5: 1.72 | N5: 6.4 | O5: 18.978 | P5: 21.325312 | Q5: 81.99151 | R5: 43.2875 | S5: 27.536 | T5: 8.77 | U5: 1.9120001 | V5: 38.67 | W5: 30.69 | X5: 5.036 | Y5: 16.97 | Z5: 20.85 | AA5: 35.9 | AB5: 20.9 | AC5: 21.5 | AD5: 11.309092 | AE5: 42.18 | AF5: 64.22 | AG5: 23
B6: 43553 | D6: 14.01 | E6: 4.85 | F6: 26.09 | G6: 7.76 | H6: 30.542 | I6: 186.89 | J6: 39.27 | K6: 50.54 | L6: 31.05 | M6: 1.668 | N6: 6.23 | O6: 18.399 | P6: 18.65731 | Q6: 89.0375 | R6: 47.4875 | S6: 30.071 | T6: 8.78 | U6: 2.11275 | V6: 39.98 | W6: 29.3 | X6: 5.905 | Y6: 19.52 | Z6: 19.646 | AA6: 38.15 | AB6: 21.17 | AC6: 21.65 | AD6: 10.527274 | AE6: 38.07 | AF6: 65.63 | AG6: 21.6
B7: 43585 | D7: 12.5 | E7: 4.45 | F7: 25.4 | G7: 8 | H7: 30.496 | I7: 204.02 | J7: 40.7 | K7: 52.08 | L7: 32.68 | M7: 1.624 | N7: 6.69 | O7: 17.177 | P7: 15.912651 | Q7: 96.326004 | R7: 50.1675 | S7: 31.84 | T7: 10.45 | U7: 2.2420003 | V7: 43.53 | W7: 28.33 | X7: 5.8286 | Y7: 20.68 | Z7: 17.818 | AA7: 35.39 | AB7: 19.13 | AC7: 21.55 | AD7: 10.364548 | AE7: 37.76 | AF7: 66.89 | AG7: 23
B8: 43616 | D8: 12.1 | E8: 3.75 | F8: 26.5 | G8: 8.2 | H8: 29.207 | I8: 195.14 | J8: 33.35 | K8: 37.44 | L8: 31.67 | M8: 1.674 | N8: 6.16 | O8: 15.957 | P8: 12.343988 | Q8: 88.7535 | R8: 43.7675 | S8: 25.164 | T8: 9.52 | U8: 1.9 | V8: 41 | W8: 21.29 | X8: 4.1716 | Y8: 21.26 | Z8: 16.79 | AA8: 35.62 | AB8: 21.8 | AC8: 21.3 | AD8: 10.409093 | AE8: 37.1 | AF8: 68.82 | AG8: 23.66
B9: 43644 | D9: 11.44 | E9: 4 | F9: 27.39 | G9: 7.87 | H9: 31.328 | I9: 199.33 | J9: 29.795 | K9: 38.33 | L9: 35.07 | M9: 1.833 | N9: 6.27 | O9: 16.891 | P9: 14.897321 | Q9: 94.68151 | R9: 49.48 | S9: 28.786 | T9: 10.23 | U9: 1.9350001 | V9: 42.28 | W9: 22.74 | X9: 4.27 | Y9: 20.04 | Z9: 16.317 | AA9: 36.75 | AB9: 21.47 | AC9: 20.825 | AD9: 10.000001 | AE9: 39.79 | AF9: 69.5 | AG9: 22.79
B10: 43677 | D10: 11.37 | E10: 4.68 | F10: 28.35 | G10: 8.11 | H10: 29.222 | I10: 191.12 | J10: 28.87 | K10: 43.42 | L10: 36.47 | M10: 1.805 | N10: 6.01 | O10: 15.791 | P10: 16.107317 | Q10: 93.339005 | R10: 53.26 | S10: 28.998999 | T10: 9.53 | U10: 1.831 | V10: 43.17 | W10: 23 | X10: 4.19114 | Y10: 21.12 | Z10: 18.499 | AA10: 36.3 | AB10: 24.53 | AC10: 21.75 | AD10: 11.136366 | AE10: 41.1 | AF10: 71.42 | AG10: 22.82
B11: 43707 | D11: 10.5 | E11: 4.3 | F11: 28.4 | G11: 8.82 | H11: 28.174 | I11: 174.05 | J11: 27.93 | K11: 38.89 | L11: 38.58 | M11: 1.777 | N11: 6.32 | O11: 13.791 | P11: 15.040653 | Q11: 88.81451 | R11: 52.185 | S11: 28.264002 | T11: 9.17 | U11: 1.89 | V11: 44.26 | W11: 18.84 | X11: 3.9 | Y11: 22.71 | Z11: 20.58 | AA11: 40.68 | AB11: 27.25 | AC11: 21.36 | AD11: 11.013639 | AE11: 41.76 | AF11: 71.36 | AG11: 21.31
B12: 43738 | D12: 9.05 | E12: 4.81 | F12: 27.25 | G12: 9.98 | H12: 29.69 | I12: 179.66 | J12: 30 | K12: 41.97 | L12: 40.32 | M12: 1.839 | N12: 6.24 | O12: 14.798 | P12: 16.057983 | Q12: 86.7955 | R12: 55.9925 | S12: 27.607 | T12: 9.16 | U12: 1.9200001 | V12: 45.08 | W12: 18.85 | X12: 4.35 | Y12: 22.91 | Z12: 18.691 | AA12: 41.79 | AB12: 25.61 | AC12: 22.525 | AD12: 10.718184 | AE12: 44.57 | AF12: 71.34 | AG12: 21.05
B13: 43769 | D13: 7.91 | E13: 5.34 | F13: 29.44 | G13: 10.15 | H13: 29.951 | I13: 182 | J13: 23.86 | K13: 49.25 | L13: 33.125 | M13: 2.019 | N13: 6.2 | O13: 14.084 | P13: 20.994648 | Q13: 88.833 | R13: 62.19 | S13: 29.285002 | T13: 8.59 | U13: 2.068 | V13: 44.82 | W13: 19.25 | X13: 4.606 | Y13: 25.66 | Z13: 20.989 | AA13: 44.04 | AB13: 25.19 | AC13: 23.675 | AD13: 11.068183 | AE13: 46.83 | AF13: 69.36 | AG13: 20.74
B14: 43798 | D14: 6.62 | E14: 6.261 | F14: 31.38 | G14: 11.05 | H14: 31.97 | I14: 193.5 | J14: 28.46 | K14: 51.27 | L14: 35.56 | M14: 2.013 | N14: 5.97 | O14: 15.801 | P14: 21.995977 | Q14: 90.04 | R14: 66.8125 | S14: 31.621 | T14: 9.06 | U14: 2.1299999 | V14: 44.15 | W14: 20.99 | X14: 4.9998 | Y14: 26.09 | Z14: 21.797 | AA14: 42.03 | AB14: 25.33 | AC14: 24.25 | AD14: 11.359092 | AE14: 54.11 | AF14: 68.77 | AG14: 21.93
B15: 43830 | D15: 6.23 | E15: 6.49 | F15: 32.08 | G15: 13 | H15: 36.449 | I15: 194.13 | J15: 27.85 | K15: 54.47 | L15: 38.11 | M15: 2.145 | N15: 5.7 | O15: 16.559 | P15: 27.88864 | Q15: 92.392 | R15: 73.4125 | S15: 31.602 | T15: 9.3 | U15: 2.4020002 | V15: 44.97 | W15: 24.47 | X15: 5.4494 | Y15: 24.81 | Z15: 22.466 | AA15: 42.35 | AB15: 25.41 | AC15: 24 | AD15: 11.786366 | AE15: 55 | AF15: 73.73 | AG15: 23
... B75: 45657 | D75: 0.771 | E75: 6.32 | F75: 24.894 | G75: 9.36 | H75: 12.796 | I75: 234.7 | J75: 8.49 | K75: 187.2 | L75: 49.32 | M75: 1.895 | N75: 3.42 | O75: 12.785 | P75: 403.84 | Q75: 219.39 | R75: 250.42 | S75: 231.84 | T75: 9.9 | U75: 30.48 | V75: 37.53 | W75: 27.19 | X75: 18.075 | Y75: 31.28 | Z75: 27.361 | AA75: 37.85 | AB75: 131.71 | AC75: 35.65 | AD75: 7.65 | AE75: 23.63 | AF75: 39.56 | AG75: 18.1
D80: Winner stocks | O80: Looser stocks | Z80: Small growth stocks | AK80: Small value stocks | AV80: Large growth stocks | BG80: Large value stocks
B81: Date | D81: VFF-US | E81: BIRDF-US | F81: BDOUY-US | G81: RPGRF-US | H81: DAY-US | I81: GLAD-US | J81: NVZMF-US | K81: AICAF-US | L81: PAYS-US | M81: FENC-US | O81: SPMYY-US | P81: AHCHY-US | Q81: NSC-US | R81: NWN-US | S81: WDFN-US | T81: DHLGY-US | U81: TEL-US | V81: YRAIF-US | W81: SSBI-US | X81: SSAAY-US | Z81: FQVTF-US | AA81: CRAI-US | AB81: CHEF-US | AC81: KALU-US | AD81: MLKN-US | AE81: DCO-US | AF81: NUV-US | AG81: NXRT-US | AH81: AAT-US | AI81: LMB-US | AK81: SCGPY-US | AL81: KOS-US | AM81: DIISY-US | AN81: SVM-US | AO81: MAG-US | AP81: GTX-US | AQ81: ORC-US | AR81: CIM-US | AS81: CHRRF-US | AT81: TORXF-US | AV81: TSLA-US | AW81: AMZN-US | AX81: AAPL-US | AY81: AVGO-US | AZ81: CSCO-US | BA81: MSFT-US | BB81: UNH-US | BC81: META-US | BD81: NVO-US | BE81: BSX-US | BG81: F-US | BH81: SMCI-US | BI81: CMCSA-US | BJ81: HAL-US | BK81: CNH-US | BL81: RNECY-US | BM81: PR-US | BN81: STLA-US | BO81: IPG-US | BP81: ABEV-US
B82: 43496 | D82: 5.5747 | E82: 4.7501 | F82: 26.51 | G82: 55.3 | H82: 41.21 | I82: 17.34 | J82: 42.42 | K82: 0.9975 | L82: 4.58 | M82: 6.69 | O82: 7.925 | P82: 27.018 | Q82: 167.74 | R82: 62.6 | S82: 29 | T82: 29.585 | U82: 80.95 | V82: 41.45 | W82: 10.705365 | X82: 1.977 | Z82: 34.3 | AA82: 41.74 | AB82: 32.12 | AC82: 100.37 | AD82: 34.23 | AE82: 39.37 | AF82: 9.67 | AG82: 37.41 | AH82: 42.94 | AI82: 5.65 | AK82: 1.452 | AL82: 5.13 | AM82: 17.716 | AN82: 2.33 | AO82: 9.01 | AP82: 15.97 | AQ82: 34.7 | AR82: 57.089943 | AS82: 37.658607 | AT82: 10.855 | AV82: 20.46798 | AW82: 85.9365 | AX82: 41.61 | AY82: 26.825 | AZ82: 47.29 | BA82: 104.43 | BB82: 270.2 | BC82: 166.69 | BD82: 23.51 | BE82: 38.15 | BG82: 8.8 | BH82: 1.5100001 | BI82: 36.57 | BJ82: 31.36 | BK82: 8.613 | BL82: 2.872 | BM82: 13.17 | BN82: 16.225363 | BO82: 22.75 | BP82: 4.81
B83: 43524 | D83: 10.58 | E83: 5.036 | F83: 25.68 | G83: 58 | H83: 49.02 | I83: 18.14 | J83: 45.515 | K83: 1.08 | L83: 7.36 | M83: 6.65 | O83: 8.04 | P83: 28.6 | Q83: 179.3 | R83: 64.22 | S83: 29.75 | T83: 31.03 | U83: 82.09 | V83: 42.15 | W83: 11.309092 | X83: 1.961 | Z83: 36.19 | AA83: 49.96 | AB83: 32.01 | AC83: 109.48 | AD83: 36.68 | AE83: 42.43 | AF83: 9.69 | AG83: 35.94 | AH83: 43.44 | AI83: 5.78 | AK83: 1.72 | AL83: 6.4 | AM83: 18.978 | AN83: 2.58 | AO83: 9.79 | AP83: 16.74 | AQ83: 33.399998 | AR83: 55.46994 | AS83: 40.880013 | AT83: 12.13 | AV83: 21.325312 | AW83: 81.99151 | AX83: 43.2875 | AY83: 27.536 | AZ83: 51.77 | BA83: 112.03 | BB83: 242.22 | BC83: 161.45 | BD83: 24.475 | BE83: 40.12 | BG83: 8.77 | BH83: 1.9120001 | BI83: 38.67 | BJ83: 30.69 | BK83: 9.456048 | BL83: 2.929 | BM83: 9.07 | BN83: 13.887251 | BO83: 23.03 | BP83: 4.53
B84: 43553 | D84: 14.01 | E84: 5.905 | F84: 26.09 | G84: 53.14 | H84: 51.3 | I84: 18.02 | J84: 46.17 | K84: 1.23 | L84: 7.95 | M84: 4.85 | O84: 7.76 | P84: 30.542 | Q84: 186.89 | R84: 65.63 | S84: 29.925 | T84: 32.555 | U84: 80.75 | V84: 41 | W84: 10.527274 | X84: 1.802 | Z84: 39.27 | AA84: 50.54 | AB84: 31.05 | AC84: 104.73 | AD84: 35.18 | AE84: 43.52 | AF84: 10 | AG84: 38.34 | AH84: 45.86 | AI84: 7.575 | AK84: 1.668 | AL84: 6.23 | AM84: 18.399 | AN84: 2.55 | AO84: 10.66 | AP84: 14.73 | AQ84: 32.9 | AR84: 56.21994 | AS84: 37.407997 | AT84: 12.6411 | AV84: 18.65731 | AW84: 89.0375 | AX84: 47.4875 | AY84: 30.071 | AZ84: 53.99 | BA84: 117.94 | BB84: 247.26 | BC84: 166.69 | BD84: 26.155 | BE84: 38.38 | BG84: 8.78 | BH84: 2.11275 | BI84: 39.98 | BJ84: 29.3 | BK84: 8.865046 | BL84: 2.313 | BM84: 8.79 | BN84: 14.000386 | BO84: 21.01 | BP84: 4.3
B85: 43585 | D85: 12.5 | E85: 5.8286 | F85: 25.4 | G85: 56.41 | H85: 53.15 | I85: 19 | J85: 46.14 | K85: 1.19 | L85: 8.13 | M85: 4.45 | O85: 8 | P85: 30.496 | Q85: 204.02 | R85: 66.89 | S85: 30.65 | T85: 34.79 | U85: 95.65 | V85: 45 | W85: 10.364548 | X85: 1.884 | Z85: 40.7 | AA85: 52.08 | AB85: 32.68 | AC85: 98.4 | AD85: 38.82 | AE85: 40.58 | AF85: 9.97 | AG85: 37.49 | AH85: 46.19 | AI85: 9.1 | AK85: 1.624 | AL85: 6.69 | AM85: 17.177 | AN85: 2.24 | AO85: 9.83 | AP85: 18.8 | AQ85: 32.850002 | AR85: 57.50994 | AS85: 38.57 | AT85: 9.54 | AV85: 15.912651 | AW85: 96.326004 | AX85: 50.1675 | AY85: 31.84 | AZ85: 55.95 | BA85: 130.6 | BB85: 233.07 | BC85: 193.4 | BD85: 24.505 | BE85: 37.12 | BG85: 10.45 | BH85: 2.2420003 | BI85: 43.53 | BJ85: 28.33 | BK85: 9.473431 | BL85: 2.662 | BM85: 10.53 | BN85: 14.528346 | BO85: 23 | BP85: 4.71
B86: 43616 | D86: 12.1 | E86: 4.1716 | F86: 26.5 | G86: 61.84 | H86: 49.18 | I86: 18 | J86: 46.36 | K86: 0.92665 | L86: 9.76 | M86: 3.75 | O86: 8.2 | P86: 29.207 | Q86: 195.14 | R86: 68.82 | S86: 30 | T86: 29.38 | U86: 84.23 | V86: 42.8 | W86: 10.409093 | X86: 1.534 | Z86: 33.35 | AA86: 37.44 | AB86: 31.67 | AC86: 89.12 | AD86: 35.49 | AE86: 45.13 | AF86: 10.07 | AG86: 40.08 | AH86: 45.39 | AI86: 9.05 | AK86: 1.674 | AL86: 6.16 | AM86: 15.957 | AN86: 2.18 | AO86: 9.77 | AP86: 15.38 | AQ86: 30.4 | AR86: 54.71994 | AS86: 38.60501 | AT86: 9.18 | AV86: 12.343988 | AW86: 88.7535 | AX86: 43.7675 | AY86: 25.164 | AZ86: 52.03 | BA86: 123.68 | BB86: 241.8 | BC86: 177.47 | BD86: 23.6 | BE86: 38.41 | BG86: 9.52 | BH86: 1.9 | BI86: 41 | BJ86: 21.29 | BK86: 7.5352883 | BL86: 2.28 | BM86: 7.9 | BN86: 11.897971 | BO86: 21.22 | BP86: 4.47
B87: 43644 | D87: 11.44 | E87: 4.27 | F87: 27.39 | G87: 67.54 | H87: 50.2 | I87: 18.76 | J87: 46.43 | K87: 1.01 | L87: 13.37 | M87: 4 | O87: 7.87 | P87: 31.328 | Q87: 199.33 | R87: 69.5 | S87: 29.55 | T87: 32.79 | U87: 95.78 | V87: 48.6 | W87: 10.000001 | X87: 1.744 | Z87: 29.795 | AA87: 38.33 | AB87: 35.07 | AC87: 97.61 | AD87: 44.7 | AE87: 45.07 | AF87: 10.18 | AG87: 41.4 | AH87: 47.12 | AI87: 9.1 | AK87: 1.833 | AL87: 6.27 | AM87: 16.891 | AN87: 2.46 | AO87: 10.54 | AP87: 15.35 | AQ87: 31.800001 | AR87: 56.60994 | AS87: 40.887703 | AT87: 10.3 | AV87: 14.897321 | AW87: 94.68151 | AX87: 49.48 | AY87: 28.786 | AZ87: 54.73 | BA87: 133.96 | BB87: 244.01 | BC87: 193 | BD87: 25.52 | BE87: 42.98 | BG87: 10.23 | BH87: 1.9350001 | BI87: 42.28 | BJ87: 22.74 | BK87: 8.934575 | BL87: 2.483 | BM87: 7.59 | BN87: 13.029315 | BO87: 22.59 | BP87: 4.67
B88: 43677 | D88: 11.37 | E88: 4.19114 | F88: 28.35 | G88: 67.045 | H88: 53.31 | I88: 18.96 | J88: 45.65 | K88: 0.98 | L88: 14.11 | M88: 4.68 | O88: 8.11 | P88: 29.222 | Q88: 191.12 | R88: 71.42 | S88: 30 | T88: 32.48 | U88: 92.4 | V88: 47.15 | W88: 11.136366 | X88: 1.433 | Z88: 28.87 | AA88: 43.42 | AB88: 36.47 | AC88: 96.27 | AD88: 45.34 | AE88: 42.15 | AF88: 10.32 | AG88: 43.16 | AH88: 46.4 | AI88: 8.88 | AK88: 1.805 | AL88: 6.01 | AM88: 15.791 | AN88: 3.07 | AO88: 11.12 | AP88: 14.17 | AQ88: 30.95 | AR88: 57.839943 | AS88: 41.839138 | AT88: 12.9 | AV88: 16.107317 | AW88: 93.339005 | AX88: 53.26 | AY88: 28.998999 | AZ88: 55.4 | BA88: 136.27 | BB88: 249.01 | BC88: 194.23 | BD88: 23.96 | BE88: 42.46 | BG88: 9.53 | BH88: 1.831 | BI88: 43.17 | BJ88: 23 | BK88: 8.786824 | BL88: 2.989 | BM88: 5.95 | BN88: 12.435359 | BO88: 22.92 | BP88: 5.27
B89: 43707 | D89: 10.5 | E89: 3.9 | F89: 28.4 | G89: 70.385 | H89: 57.77 | I89: 18.64 | J89: 42.2 | K89: 0.8673 | L89: 13.29 | M89: 4.3 | O89: 8.82 | P89: 28.174 | Q89: 174.05 | R89: 71.36 | S89: 31.75 | T89: 32.82 | U89: 91.22 | V89: 43.42 | W89: 11.013639 | X89: 1.386 | Z89: 27.93 | AA89: 38.89 | AB89: 38.58 | AC89: 88.43 | AD89: 42.28 | AE89: 41.18 | AF89: 10.53 | AG89: 46.4 | AH89: 46.86 | AI89: 4.84 | AK89: 1.777 | AL89: 6.32 | AM89: 13.791 | AN89: 4.29 | AO89: 12.75 | AP89: 9.84 | AQ89: 27.15 | AR89: 57.20994 | AS89: 38.77497 | AT89: 16.064 | AV89: 15.040653 | AW89: 88.81451 | AX89: 52.185 | AY89: 28.264002 | AZ89: 46.81 | BA89: 137.86 | BB89: 234 | BC89: 185.67 | BD89: 26.055 | BE89: 42.73 | BG89: 9.17 | BH89: 1.89 | BI89: 44.26 | BJ89: 18.84 | BK89: 8.917192 | BL89: 3.128 | BM89: 4.82 | BN89: 12.388221 | BO89: 19.88 | BP89: 4.54
B90: 43738 | D90: 9.05 | E90: 4.35 | F90: 27.25 | G90: 73.04 | H90: 49.37 | I90: 19.5 | J90: 42.08 | K90: 0.8775 | L90: 10.1 | M90: 4.81 | O90: 9.98 | P90: 29.69 | Q90: 179.66 | R90: 71.34 | S90: 31.275 | T90: 33.26 | U90: 93.18 | V90: 43.135 | W90: 10.718184 | X90: 1.393 | Z90: 30 | AA90: 41.97 | AB90: 40.32 | AC90: 98.97 | AD90: 46.09 | AE90: 42.4 | AF90: 10.51 | AG90: 46.76 | AH90: 46.74 | AI90: 4.93 | AK90: 1.839 | AL90: 6.24 | AM90: 14.798 | AN90: 3.89 | AO90: 10.61 | AP90: 9.96 | AQ90: 28.75 | AR90: 58.67994 | AS90: 40.250015 | AT90: 12.4007 | AV90: 16.057983 | AW90: 86.7955 | AX90: 55.9925 | AY90: 27.607 | AZ90: 49.41 | BA90: 139.03 | BB90: 217.32 | BC90: 178.08 | BD90: 25.85 | BE90: 40.69 | BG90: 9.16 | BH90: 1.9200001 | BI90: 45.08 | BJ90: 18.85 | BK90: 8.8215885 | BL90: 3.248 | BM90: 4.515 | BN90: 12.20909 | BO90: 21.56 | BP90: 4.62
B91: 43769 | D91: 7.91 | E91: 4.606 | F91: 29.44 | G91: 74.5 | H91: 48.25 | I91: 19.74 | J91: 47.0606 | K91: 0.8848 | L91: 10.78 | M91: 5.34 | O91: 10.15 | P91: 29.951 | Q91: 182 | R91: 69.36 | S91: 31.5 | T91: 35.45 | U91: 89.5 | V91: 38.95 | W91: 11.068183 | X91: 1.399 | Z91: 23.86 | AA91: 49.25 | AB91: 33.125 | AC91: 107.08 | AD91: 46.5 | AE91: 49.58 | AF91: 10.43 | AG91: 48.77 | AH91: 48.96 | AI91: 4.5 | AK91: 2.019 | AL91: 6.2 | AM91: 14.084 | AN91: 4.17 | AO91: 9.86 | AP91: 9.5 | AQ91: 27.85 | AR91: 60.779938 | AS91: 41.109528 | AT91: 14.6455 | AV91: 20.994648 | AW91: 88.833 | AX91: 62.19 | AY91: 29.285002 | AZ91: 47.51 | BA91: 143.37 | BB91: 252.7 | BC91: 191.65 | BD91: 27.61 | BE91: 41.7 | BG91: 8.59 | BH91: 2.068 | BI91: 44.82 | BJ91: 19.25 | BK91: 9.482121 | BL91: 3.423 | BM91: 3.4 | BN91: 14.443496 | BO91: 21.75 | BP91: 4.31
B92: 43798 | D92: 6.62 | E92: 4.9998 | F92: 31.38 | G92: 70.92 | H92: 60.36 | I92: 20.82 | J92: 47.49 | K92: 0.92 | L92: 10.26 | M92: 6.261 | O92: 11.05 | P92: 31.97 | Q92: 193.5 | R92: 68.77 | S92: 32.125 | T92: 37.2385 | U92: 92.71 | V92: 37.6 | W92: 11.359092 | X92: 1.557 | Z92: 28.46 | AA92: 51.27 | AB92: 35.56 | AC92: 109.58 | AD92: 47.78 | AE92: 48.88 | AF92: 10.51 | AG92: 47.85 | AH92: 47.53 | AI92: 3 | AK92: 2.013 | AL92: 5.97 | AM92: 15.801 | AN92: 5.12 | AO92: 10.69 | AP92: 11.57 | AQ92: 28.4 | AR92: 61.10994 | AS92: 42.850502 | AT92: 14.975 | AV92: 21.995977 | AW92: 90.04 | AX92: 66.8125 | AY92: 31.621 | AZ92: 45.31 | BA92: 151.38 | BB92: 279.87 | BC92: 201.64 | BD92: 28.075 | BE92: 43.25 | BG92: 9.06 | BH92: 2.1299999 | BI92: 44.15 | BJ92: 20.99 | BK92: 9.343062 | BL92: 3.255 | BM92: 3.09 | BN92: 13.906107 | BO92: 22.4 | BP92: 4.21
B93: 43830 | D93: 6.23 | E93: 5.4494 | F93: 32.08 | G93: 72.515 | H93: 67.88 | I93: 19.86 | J93: 49.18 | K93: 1 | L93: 10.15 | M93: 6.49 | O93: 13 | P93: 36.449 | Q93: 194.13 | R93: 73.73 | S93: 32.75 | T93: 37.82 | U93: 95.84 | V93: 41.575 | W93: 11.786366 | X93: 1.755 | Z93: 27.85 | AA93: 54.47 | AB93: 38.11 | AC93: 110.89 | AD93: 41.65 | AE93: 50.53 | AF93: 10.7 | AG93: 45 | AH93: 45.9 | AI93: 3.78 | AK93: 2.145 | AL93: 5.7 | AM93: 16.559 | AN93: 5.67 | AO93: 11.84 | AP93: 9.99 | AQ93: 29.25 | AR93: 61.679935 | AS93: 43.144363 | AT93: 15.8 | AV93: 27.88864 | AW93: 92.392 | AX93: 73.4125 | AY93: 31.602 | AZ93: 47.96 | BA93: 157.7 | BB93: 293.98 | BC93: 205.25 | BD93: 28.94 | BE93: 45.22 | BG93: 9.3 | BH93: 2.4020002 | BI93: 44.97 | BJ93: 24.47 | BK93: 9.560343 | BL93: 3.451 | BM93: 4.62 | BN93: 13.84954 | BO93: 23.1 | BP93: 4.66
... B153: 45657 | D153: 0.771 | E153: 18.075 | F153: 24.894 | G153: 145.43 | H153: 72.64 | I153: 28.44 | J153: 54.86 | K153: 0.655 | L153: 3.02 | M153: 6.32 | O153: 9.36 | P153: 12.796 | Q153: 234.7 | R153: 39.56 | S153: 20.175 | T153: 34.9 | U153: 142.97 | V153: 26.635 | W153: 7.65 | X153: 2.035 | Z153: 8.49 | AA153: 187.2 | AB153: 49.32 | AC153: 70.27 | AD153: 22.59 | AE153: 63.66 | AF153: 8.59 | AG153: 41.75 | AH153: 26.26 | AI153: 85.54 | AK153: 1.895 | AL153: 3.42 | AM153: 12.785 | AN153: 3 | AO153: 13.6 | AP153: 9.03 | AQ153: 7.78 | AR153: 14 | AS153: 15.120004 | AT153: 19.574 | AV153: 403.84 | AW153: 219.39 | AX153: 250.42 | AY153: 231.84 | AZ153: 59.2 | BA153: 421.5 | BB153: 505.86 | BC153: 585.51 | BD153: 86.02 | BE153: 89.32 | BG153: 9.9 | BH153: 30.48 | BI153: 37.53 | BJ153: 27.19 | BK153: 11.33 | BL153: 6.511 | BM153: 14.38 | BN153: 13.05 | BO153: 28.02 | BP153: 1.85
D158: Long position | T158: Short position
B159: Date | D159: BIRDF-US | E159: EPRT-US | F159: OTSKY-US | G159: OHI-US | H159: AGYS-US | I159: SAPMY-US | J159: UTHR-US | K159: APO-US | L159: PAYS-US | M159: POWL-US | N159: JEF-US | O159: LAZ-US | P159: PCYO-US | Q159: FNF-US | R159: ITRI-US | T159: AHCHY-US | U159: SSBI-US | V159: NSC-US | W159: NWN-US | X159: MNSB-US | Y159: CWBK-US | Z159: PLOW-US | AA159: WPC-US | AB159: FBTT-US | AC159: ESCA-US | AD159: SPOK-US | AE159: UNLYF-US | AF159: DHLGY-US | AG159: TEL-US | AH159: YRAIF-US
B160: 43496 | D160: 4.7501 | E160: 15.9 | F160: 20.459 | G160: 40.19 | H160: 17.7 | I160: 45.361908 | J160: 115.33 | K160: 29.28 | L160: 4.58 | M160: 27.91 | N160: 18.610497 | O160: 39.79 | P160: 10.17 | Q160: 34.759365 | R160: 54.63 | T160: 27.018 | U160: 10.705365 | V160: 167.74 | W160: 62.6 | X160: 19.85 | Y160: 19.5 | Z160: 35.4 | AA160: 73.31628 | AB160: 33 | AC160: 11.16 | AD160: 13.84 | AE160: 52.455 | AF160: 29.585 | AG160: 80.95 | AH160: 41.45
B161: 43524 | D161: 5.036 | E161: 16.97 | F161: 20.85 | G161: 35.9 | H161: 20.9 | I161: 49.504765 | J161: 126.29 | K161: 29.3 | L161: 7.36 | M161: 32.09 | N161: 18.127571 | O161: 37.43 | P161: 10.14 | Q161: 33.730812 | R161: 53.01 | T161: 28.6 | U161: 11.309092 | V161: 179.3 | W161: 64.22 | X161: 23 | Y161: 21.5 | Z161: 42.18 | AA161: 72.31771 | AB161: 36 | AC161: 12.2 | AD161: 13.81 | AE161: 53.2 | AF161: 31.03 | AG161: 82.09 | AH161: 42.15
B162: 43553 | D162: 5.905 | E162: 19.52 | F162: 19.646 | G162: 38.15 | H162: 21.17 | I162: 50.423817 | J162: 117.37 | K162: 28.25 | L162: 7.95 | M162: 26.55 | N162: 16.804 | O162: 36.14 | P162: 9.86 | Q162: 35.13426 | R162: 46.65 | T162: 30.542 | U162: 10.527274 | V162: 186.89 | W162: 65.63 | X162: 21.6 | Y162: 21.65 | Z162: 38.07 | AA162: 76.68399 | AB162: 34.625 | AC162: 11.17 | AD162: 13.62 | AE162: 57.75 | AF162: 32.555 | AG162: 80.75 | AH162: 41
B163: 43585 | D163: 5.8286 | E163: 20.68 | F163: 17.818 | G163: 35.39 | H163: 19.13 | I163: 48.20953 | J163: 102.57 | K163: 32.69 | L163: 8.13 | M163: 29.25 | N163: 18.395864 | O163: 38.88 | P163: 10.05 | Q163: 38.40256 | R163: 53.66 | T163: 30.496 | U163: 10.364548 | V163: 204.02 | W163: 66.89 | X163: 23 | Y163: 21.55 | Z163: 37.76 | AA163: 77.65318 | AB163: 33.85 | AC163: 12.04 | AD163: 13.85 | AE163: 60.45 | AF163: 34.79 | AG163: 95.65 | AH163: 45
B164: 43616 | D164: 4.1716 | E164: 21.26 | F164: 16.79 | G164: 35.62 | H164: 21.8 | I164: 40.680958 | J164: 83.97 | K164: 29.41 | L164: 9.76 | M164: 34.42 | N164: 15.802378 | O164: 31.16 | P164: 9.42 | Q164: 37.05679 | R164: 56.65 | T164: 29.207 | U164: 10.409093 | V164: 195.14 | W164: 68.82 | X164: 23.66 | Y164: 21.3 | Z164: 37.1 | AA164: 81.26565 | AB164: 33.5 | AC164: 11.13 | AD164: 15.45 | AE164: 61.05 | AF164: 29.38 | AG164: 84.23 | AH164: 42.8
B165: 43644 | D165: 4.27 | E165: 20.04 | F165: 16.317 | G165: 36.75 | H165: 21.47 | I165: 47.452385 | J165: 78.06 | K165: 34.3 | L165: 13.37 | M165: 38 | N165: 17.197493 | O165: 34.39 | P165: 10.6 | Q165: 38.739002 | R165: 62.57 | T165: 31.328 | U165: 10.000001 | V165: 199.33 | W165: 69.5 | X165: 22.79 | Y165: 20.825 | Z165: 39.79 | AA165: 79.4741 | AB165: 31.5 | AC165: 11.47 | AD165: 15.04 | AE165: 61.6998 | AF165: 32.79 | AG165: 95.78 | AH165: 48.6
B166: 43677 | D166: 4.19114 | E166: 21.12 | F166: 18.499 | G166: 36.3 | H166: 24.53 | I166: 47.633343 | J166: 79.24 | K166: 33 | L166: 14.11 | M166: 36.99 | N166: 19.075535 | O166: 38.71 | P166: 10.87 | Q166: 41.21907 | R166: 62 | T166: 29.222 | U166: 11.136366 | V166: 191.12 | W166: 71.42 | X166: 22.82 | Y166: 21.75 | Z166: 41.1 | AA166: 84.721466 | AB166: 31.25 | AC166: 11.53 | AD166: 12.99 | AE166: 60.225 | AF166: 32.48 | AG166: 92.4 | AH166: 47.15
B167: 43707 | D167: 3.9 | E167: 22.71 | F167: 20.58 | G167: 40.68 | H167: 27.25 | I167: 45.35239 | J167: 82.56 | K167: 37.73 | L167: 13.29 | M167: 36.32 | N167: 16.669853 | O167: 34.34 | P167: 10.85 | Q167: 42.23801 | R167: 69.45 | T167: 28.174 | U167: 11.013639 | V167: 174.05 | W167: 71.36 | X167: 21.31 | Y167: 21.36 | Z167: 41.76 | AA167: 87.912964 | AB167: 31.075 | AC167: 10.33 | AD167: 11.75 | AE167: 62.6 | AF167: 32.82 | AG167: 91.22 | AH167: 43.42
...

Sheet Question 1 - Prices
C1: Mean-Variance Optimization
A2: Date | C2: VFF-US | D2: FENC-US | E2: BDOUY-US | F2: SPMYY-US | G2: AHCHY-US | H2: NSC-US | I2: FQVTF-US | J2: CRAI-US | K2: CHEF-US | L2: SCGPY-US | M2: KOS-US | N2: DIISY-US | O2: TSLA-US | P2: AMZN-US | Q2: AAPL-US | R2: AVGO-US | S2: F-US | T2: SMCI-US | U2: CMCSA-US | V2: HAL-US | W2: BIRDF-US | X2: EPRT-US | Y2: OTSKY-US | Z2: OHI-US | AA2: AGYS-US
A3: 43496 | C3: 5.5747 | D3: 6.69 | E3: 26.51 | F3: 7.925 | G3: 27.018 | H3: 167.74 | I3: 34.3 | J3: 41.74 | K3: 32.12 | L3: 1.452 | M3: 5.13 | N3: 17.716 | O3: 20.46798 | P3: 85.9365 | Q3: 41.61 | R3: 26.825 | S3: 8.8 | T3: 1.5100001 | U3: 36.57 | V3: 31.36 | W3: 4.7501 | X3: 15.9 | Y3: 20.459 | Z3: 40.19 | AA3: 17.7
A4: 43524 | C4: 10.58 | D4: 6.65 | E4: 25.68 | F4: 8.04 | G4: 28.6 | H4: 179.3 | I4: 36.19 | J4: 49.96 | K4: 32.01 | L4: 1.72 | M4: 6.4 | N4: 18.978 | O4: 21.325312 | P4: 81.99151 | Q4: 43.2875 | R4: 27.536 | S4: 8.77 | T4: 1.9120001 | U4: 38.67 | V4: 30.69 | W4: 5.036 | X4: 16.97 | Y4: 20.85 | Z4: 35.9 | AA4: 20.9
A5: 43553 | C5: 14.01 | D5: 4.85 | E5: 26.09 | F5: 7.76 | G5: 30.542 | H5: 186.89 | I5: 39.27 | J5: 50.54 | K5: 31.05 | L5: 1.668 | M5: 6.23 | N5: 18.399 | O5: 18.65731 | P5: 89.0375 | Q5: 47.4875 | R5: 30.071 | S5: 8.78 | T5: 2.11275 | U5: 39.98 | V5: 29.3 | W5: 5.905 | X5: 19.52 | Y5: 19.646 | Z5: 38.15 | AA5: 21.17
A6: 43585 | C6: 12.5 | D6: 4.45 | E6: 25.4 | F6: 8 | G6: 30.496 | H6: 204.02 | I6: 40.7 | J6: 52.08 | K6: 32.68 | L6: 1.624 | M6: 6.69 | N6: 17.177 | O6: 15.912651 | P6: 96.326004 | Q6: 50.1675 | R6: 31.84 | S6: 10.45 | T6: 2.2420003 | U6: 43.53 | V6: 28.33 | W6: 5.8286 | X6: 20.68 | Y6: 17.818 | Z6: 35.39 | AA6: 19.13
A7: 43616 | C7: 12.1 | D7: 3.75 | E7: 26.5 | F7: 8.2 | G7: 29.207 | H7: 195.14 | I7: 33.35 | J7: 37.44 | K7: 31.67 | L7: 1.674 | M7: 6.16 | N7: 15.957 | O7: 12.343988 | P7: 88.7535 | Q7: 43.7675 | R7: 25.164 | S7: 9.52 | T7: 1.9 | U7: 41 | V7: 21.29 | W7: 4.1716 | X7: 21.26 | Y7: 16.79 | Z7: 35.62 | AA7: 21.8
A8: 43644 | C8: 11.44 | D8: 4 | E8: 27.39 | F8: 7.87 | G8: 31.328 | H8: 199.33 | I8: 29.795 | J8: 38.33 | K8: 35.07 | L8: 1.833 | M8: 6.27 | N8: 16.891 | O8: 14.897321 | P8: 94.68151 | Q8: 49.48 | R8: 28.786 | S8: 10.23 | T8: 1.9350001 | U8: 42.28 | V8: 22.74 | W8: 4.27 | X8: 20.04 | Y8: 16.317 | Z8: 36.75 | AA8: 21.47
A9: 43677 | C9: 11.37 | D9: 4.68 | E9: 28.35 | F9: 8.11 | G9: 29.222 | H9: 191.12 | I9: 28.87 | J9: 43.42 | K9: 36.47 | L9: 1.805 | M9: 6.01 | N9: 15.791 | O9: 16.107317 | P9: 93.339005 | Q9: 53.26 | R9: 28.998999 | S9: 9.53 | T9: 1.831 | U9: 43.17 | V9: 23 | W9: 4.19114 | X9: 21.12 | Y9: 18.499 | Z9: 36.3 | AA9: 24.53
A10: 43707 | C10: 10.5 | D10: 4.3 | E10: 28.4 | F10: 8.82 | G10: 28.174 | H10: 174.05 | I10: 27.93 | J10: 38.89 | K10: 38.58 | L10: 1.777 | M10: 6.32 | N10: 13.791 | O10: 15.040653 | P10: 88.81451 | Q10: 52.185 | R10: 28.264002 | S10: 9.17 | T10: 1.89 | U10: 44.26 | V10: 18.84 | W10: 3.9 | X10: 22.71 | Y10: 20.58 | Z10: 40.68 | AA10: 27.25
A11: 43738 | C11: 9.05 | D11: 4.81 | E11: 27.25 | F11: 9.98 | G11: 29.69 | H11: 179.66 | I11: 30 | J11: 41.97 | K11: 40.32 | L11: 1.839 | M11: 6.24 | N11: 14.798 | O11: 16.057983 | P11: 86.7955 | Q11: 55.9925 | R11: 27.607 | S11: 9.16 | T11: 1.9200001 | U11: 45.08 | V11: 18.85 | W11: 4.35 | X11: 22.91 | Y11: 18.691 | Z11: 41.79 | AA11: 25.61
A12: 43769 | C12: 7.91 | D12: 5.34 | E12: 29.44 | F12: 10.15 | G12: 29.951 | H12: 182 | I12: 23.86 | J12: 49.25 | K12: 33.125 | L12: 2.019 | M12: 6.2 | N12: 14.084 | O12: 20.994648 | P12: 88.833 | Q12: 62.19 | R12: 29.285002 | S12: 8.59 | T12: 2.068 | U12: 44.82 | V12: 19.25 | W12: 4.606 | X12: 25.66 | Y12: 20.989 | Z12: 44.04 | AA12: 25.19
A13: 43798 | C13: 6.62 | D13: 6.261 | E13: 31.38 | F13: 11.05 | G13: 31.97 | H13: 193.5 | I13: 28.46 | J13: 51.27 | K13: 35.56 | L13: 2.013 | M13: 5.97 | N13: 15.801 | O13: 21.995977 | P13: 90.04 | Q13: 66.8125 | R13: 31.621 | S13: 9.06 | T13: 2.1299999 | U13: 44.15 | V13: 20.99 | W13: 4.9998 | X13: 26.09 | Y13: 21.797 | Z13: 42.03 | AA13: 25.33
A14: 43830 | C14: 6.23 | D14: 6.49 | E14: 32.08 | F14: 13 | G14: 36.449 | H14: 194.13 | I14: 27.85 | J14: 54.47 | K14: 38.11 | L14: 2.145 | M14: 5.7 | N14: 16.559 | O14: 27.88864 | P14: 92.392 | Q14: 73.4125 | R14: 31.602 | S14: 9.3 | T14: 2.4020002 | U14: 44.97 | V14: 24.47 | W14: 5.4494 | X14: 24.81 | Y14: 22.466 | Z14: 42.35 | AA14: 25.41
... A74: 45657 | C74: 0.771 | D74: 6.32 | E74: 24.894 | F74: 9.36 | G74: 12.796 | H74: 234.7 | I74: 8.49 | J74: 187.2 | K74: 49.32 | L74: 1.895 | M74: 3.42 | N74: 12.785 | O74: 403.84 | P74: 219.39 | Q74: 250.42 | R74: 231.84 | S74: 9.9 | T74: 30.48 | U74: 37.53 | V74: 27.19 | W74: 18.075 | X74: 31.28 | Y74: 27.361 | Z74: 37.85 | AA74: 131.71

Sheet Question 1 - Return
A1: Date | B1: VFF-US | C1: FENC-US | D1: BDOUY-US | E1: SPMYY-US | F1: AHCHY-US | G1: NSC-US | H1: FQVTF-US | I1: CRAI-US | J1: CHEF-US | K1: SCGPY-US | L1: KOS-US | M1: DIISY-US | N1: TSLA-US | O1: AMZN-US | P1: AAPL-US | Q1: AVGO-US | R1: F-US | S1: SMCI-US | T1: CMCSA-US | U1: HAL-US | V1: BIRDF-US | W1: EPRT-US | X1: OTSKY-US | Y1: OHI-US | Z1: AGYS-US | AB1: Excess Return | AC1: VFF-US | AD1: FENC-US | AE1: BDOUY-US | AF1: SPMYY-US | AG1: AHCHY-US | AH1: NSC-US | AI1: FQVTF-US | AJ1: CRAI-US | AK1: CHEF-US | AL1: SCGPY-US | AM1: KOS-US | AN1: DIISY-US | AO1: TSLA-US | AP1: AMZN-US | AQ1: AAPL-US | AR1: AVGO-US | AS1: F-US | AT1: SMCI-US | AU1: CMCSA-US | AV1: HAL-US | AW1: BIRDF-US | AX1: EPRT-US | AY1: OTSKY-US | AZ1: OHI-US | BA1: AGYS-US | BD1: ST.DEV
A2: 43496 | BC2: VFF-US | BD2: 0.27615672
A3: 43524 | B3: =('Question 1 - Prices'!C4-'Question 1 - Prices'!C3)/'Question 1 - Prices'!C3 -> 0.89785997 | C3: =('Question 1 - Prices'!D4-'Question 1 - Prices'!D3)/'Question 1 - Prices'!D3 -> -0.0059790732 | D3: =('Question 1 - Prices'!E4-'Question 1 - Prices'!E3)/'Question 1 - Prices'!E3 -> -0.03130894 | E3: =('Question 1 - Prices'!F4-'Question 1 - Prices'!F3)/'Question 1 - Prices'!F3 -> 0.014511041 | F3: =('Question 1 - Prices'!G4-'Question 1 - Prices'!G3)/'Question 1 - Prices'!G3 -> 0.058553557 | G3: =('Question 1 - Prices'!H4-'Question 1 - Prices'!H3)/'Question 1 - Prices'!H3 -> 0.06891618 | H3: =('Question 1 - Prices'!I4-'Question 1 - Prices'!I3)/'Question 1 - Prices'!I3 -> 0.055102041 | I3: =('Question 1 - Prices'!J4-'Question 1 - Prices'!J3)/'Question 1 - Prices'!J3 -> 0.1969334 | ... Z3: =('Question 1 - Prices'!AA4-'Question 1 - Prices'!AA3)/'Question 1 - Prices'!AA3 -> 0.18079096 | AC3: =B3-B$62 -> 0.90194713 | AD3: =C3-C$62 -> -0.026743013 | AE3: =D3-D$62 -> -0.033490953 | AF3: =E3-E$62 -> 0.01321533 | AG3: =F3-F$62 -> 0.068209978 | AH3: =G3-G$62 -> 0.05961511 | AI3: =H3-H$62 -> 0.060834258 | AJ3: =I3-I$62 -> 0.1759683 | ... BA3: =Z3-Z$62 -> 0.1428744 | BC3: FENC-US | BD3: 0.15043912
A4: 43553 | B4: =('Question 1 - Prices'!C5-'Question 1 - Prices'!C4)/'Question 1 - Prices'!C4 -> 0.3241966 | C4: =('Question 1 - Prices'!D5-'Question 1 - Prices'!D4)/'Question 1 - Prices'!D4 -> -0.27067669 | D4: =('Question 1 - Prices'!E5-'Question 1 - Prices'!E4)/'Question 1 - Prices'!E4 -> 0.015965732 | E4: =('Question 1 - Prices'!F5-'Question 1 - Prices'!F4)/'Question 1 - Prices'!F4 -> -0.034825871 | F4: =('Question 1 - Prices'!G5-'Question 1 - Prices'!G4)/'Question 1 - Prices'!G4 -> 0.067902098 | G4: =('Question 1 - Prices'!H5-'Question 1 - Prices'!H4)/'Question 1 - Prices'!H4 -> 0.042331288 | H4: =('Question 1 - Prices'!I5-'Question 1 - Prices'!I4)/'Question 1 - Prices'!I4 -> 0.085106383 | I4: =('Question 1 - Prices'!J5-'Question 1 - Prices'!J4)/'Question 1 - Prices'!J4 -> 0.011609287 | ... Z4: =('Question 1 - Prices'!AA5-'Question 1 - Prices'!AA4)/'Question 1 - Prices'!AA4 -> 0.01291866 | AC4: =B4-B$62 -> 0.32828375 | AD4: =C4-C$62 -> -0.29144063 | AE4: =D4-D$62 -> 0.013783719 | AF4: =E4-E$62 -> -0.036121582 | AG4: =F4-F$62 -> 0.077558519 | AH4: =G4-G$62 -> 0.033030219 | AI4: =H4-H$62 -> 0.0908386 | AJ4: =I4-I$62 -> -0.0093558101 | ... BA4: =Z4-Z$62 -> -0.024997903 | BC4: BDOUY-US | BD4: 0.086733407
A5: 43585 | B5: =('Question 1 - Prices'!C6-'Question 1 - Prices'!C5)/'Question 1 - Prices'!C5 -> -0.10778016 | C5: =('Question 1 - Prices'!D6-'Question 1 - Prices'!D5)/'Question 1 - Prices'!D5 -> -0.082474227 | D5: =('Question 1 - Prices'!E6-'Question 1 - Prices'!E5)/'Question 1 - Prices'!E5 -> -0.026446915 | E5: =('Question 1 - Prices'!F6-'Question 1 - Prices'!F5)/'Question 1 - Prices'!F5 -> 0.030927835 | F5: =('Question 1 - Prices'!G6-'Question 1 - Prices'!G5)/'Question 1 - Prices'!G5 -> -0.0015061227 | G5: =('Question 1 - Prices'!H6-'Question 1 - Prices'!H5)/'Question 1 - Prices'!H5 -> 0.091658195 | H5: =('Question 1 - Prices'!I6-'Question 1 - Prices'!I5)/'Question 1 - Prices'!I5 -> 0.036414566 | I5: =('Question 1 - Prices'!J6-'Question 1 - Prices'!J5)/'Question 1 - Prices'!J5 -> 0.030470914 | ... Z5: =('Question 1 - Prices'!AA6-'Question 1 - Prices'!AA5)/'Question 1 - Prices'!AA5 -> -0.096362778 | AC5: =B5-B$62 -> -0.103693 | AD5: =C5-C$62 -> -0.10323817 | AE5: =D5-D$62 -> -0.028628927 | AF5: =E5-E$62 -> 0.029632124 | AG5: =F5-F$62 -> 0.0081502982 | AH5: =G5-G$62 -> 0.082357125 | AI5: =H5-H$62 -> 0.042146783 | AJ5: =I5-I$62 -> 0.0095058166 | ... BA5: =Z5-Z$62 -> -0.13427934 | BC5: SPMYY-US | BD5: 0.13625678
A6: 43616 | B6: =('Question 1 - Prices'!C7-'Question 1 - Prices'!C6)/'Question 1 - Prices'!C6 -> -0.032 | C6: =('Question 1 - Prices'!D7-'Question 1 - Prices'!D6)/'Question 1 - Prices'!D6 -> -0.15730337 | D6: =('Question 1 - Prices'!E7-'Question 1 - Prices'!E6)/'Question 1 - Prices'!E6 -> 0.043307087 | E6: =('Question 1 - Prices'!F7-'Question 1 - Prices'!F6)/'Question 1 - Prices'!F6 -> 0.025 | F6: =('Question 1 - Prices'!G7-'Question 1 - Prices'!G6)/'Question 1 - Prices'!G6 -> -0.042267838 | G6: =('Question 1 - Prices'!H7-'Question 1 - Prices'!H6)/'Question 1 - Prices'!H6 -> -0.043525145 | H6: =('Question 1 - Prices'!I7-'Question 1 - Prices'!I6)/'Question 1 - Prices'!I6 -> -0.18058968 | I6: =('Question 1 - Prices'!J7-'Question 1 - Prices'!J6)/'Question 1 - Prices'!J6 -> -0.28110599 | ... Z6: =('Question 1 - Prices'!AA7-'Question 1 - Prices'!AA6)/'Question 1 - Prices'!AA6 -> 0.13957135 | AC6: =B6-B$62 -> -0.027912847 | AD6: =C6-C$62 -> -0.17806731 | AE6: =D6-D$62 -> 0.041125074 | AF6: =E6-E$62 -> 0.023704289 | AG6: =F6-F$62 -> -0.032611417 | AH6: =G6-G$62 -> -0.052826214 | AI6: =H6-H$62 -> -0.17485746 | AJ6: =I6-I$62 -> -0.30207109 | ... BA6: =Z6-Z$62 -> 0.10165479 | BC6: AHCHY-US | BD6: 0.10490687
A7: 43644 | B7: =('Question 1 - Prices'!C8-'Question 1 - Prices'!C7)/'Question 1 - Prices'!C7 -> -0.054545455 | C7: =('Question 1 - Prices'!D8-'Question 1 - Prices'!D7)/'Question 1 - Prices'!D7 -> 0.066666667 | D7: =('Question 1 - Prices'!E8-'Question 1 - Prices'!E7)/'Question 1 - Prices'!E7 -> 0.033584906 | E7: =('Question 1 - Prices'!F8-'Question 1 - Prices'!F7)/'Question 1 - Prices'!F7 -> -0.040243902 | F7: =('Question 1 - Prices'!G8-'Question 1 - Prices'!G7)/'Question 1 - Prices'!G7 -> 0.072619577 | G7: =('Question 1 - Prices'!H8-'Question 1 - Prices'!H7)/'Question 1 - Prices'!H7 -> 0.021471764 | H7: =('Question 1 - Prices'!I8-'Question 1 - Prices'!I7)/'Question 1 - Prices'!I7 -> -0.1065967 | I7: =('Question 1 - Prices'!J8-'Question 1 - Prices'!J7)/'Question 1 - Prices'!J7 -> 0.023771368 | ... Z7: =('Question 1 - Prices'!AA8-'Question 1 - Prices'!AA7)/'Question 1 - Prices'!AA7 -> -0.015137615 | AC7: =B7-B$62 -> -0.050458301 | AD7: =C7-C$62 -> 0.045902727 | AE7: =D7-D$62 -> 0.031402893 | AF7: =E7-E$62 -> -0.041539613 | AG7: =F7-F$62 -> 0.082275998 | AH7: =G7-G$62 -> 0.012170694 | AI7: =H7-H$62 -> -0.10086448 | AJ7: =I7-I$62 -> 0.00280627 | ... BA7: =Z7-Z$62 -> -0.053054178 | BC7: NSC-US | BD7: 0.083175772
A8: 43677 | B8: =('Question 1 - Prices'!C9-'Question 1 - Prices'!C8)/'Question 1 - Prices'!C8 -> -0.0061188811 | C8: =('Question 1 - Prices'!D9-'Question 1 - Prices'!D8)/'Question 1 - Prices'!D8 -> 0.17 | D8: =('Question 1 - Prices'!E9-'Question 1 - Prices'!E8)/'Question 1 - Prices'!E8 -> 0.035049288 | E8: =('Question 1 - Prices'!F9-'Question 1 - Prices'!F8)/'Question 1 - Prices'!F8 -> 0.030495553 | F8: =('Question 1 - Prices'!G9-'Question 1 - Prices'!G8)/'Question 1 - Prices'!G8 -> -0.067224208 | G8: =('Question 1 - Prices'!H9-'Question 1 - Prices'!H8)/'Question 1 - Prices'!H8 -> -0.04118798 | H8: =('Question 1 - Prices'!I9-'Question 1 - Prices'!I8)/'Question 1 - Prices'!I8 -> -0.031045477 | I8: =('Question 1 - Prices'!J9-'Question 1 - Prices'!J8)/'Question 1 - Prices'!J8 -> 0.13279416 | ... Z8: =('Question 1 - Prices'!AA9-'Question 1 - Prices'!AA8)/'Question 1 - Prices'!AA8 -> 0.14252445 | AC8: =B8-B$62 -> -0.0020317277 | AD8: =C8-C$62 -> 0.14923606 | AE8: =D8-D$62 -> 0.032867275 | AF8: =E8-E$62 -> 0.029199842 | AG8: =F8-F$62 -> -0.057567787 | AH8: =G8-G$62 -> -0.050489049 | AI8: =H8-H$62 -> -0.02531326 | AJ8: =I8-I$62 -> 0.11182906 | ... BA8: =Z8-Z$62 -> 0.10460789 | BC8: FQVTF-US | BD8: 0.13443418
A9: 43707 | B9: =('Question 1 - Prices'!C10-'Question 1 - Prices'!C9)/'Question 1 - Prices'!C9 -> -0.07651715 | C9: =('Question 1 - Prices'!D10-'Question 1 - Prices'!D9)/'Question 1 - Prices'!D9 -> -0.081196581 | D9: =('Question 1 - Prices'!E10-'Question 1 - Prices'!E9)/'Question 1 - Prices'!E9 -> 0.0017636684 | E9: =('Question 1 - Prices'!F10-'Question 1 - Prices'!F9)/'Question 1 - Prices'!F9 -> 0.087546239 | F9: =('Question 1 - Prices'!G10-'Question 1 - Prices'!G9)/'Question 1 - Prices'!G9 -> -0.035863391 | G9: =('Question 1 - Prices'!H10-'Question 1 - Prices'!H9)/'Question 1 - Prices'!H9 -> -0.089315613 | H9: =('Question 1 - Prices'!I10-'Question 1 - Prices'!I9)/'Question 1 - Prices'!I9 -> -0.032559751 | I9: =('Question 1 - Prices'!J10-'Question 1 - Prices'!J9)/'Question 1 - Prices'!J9 -> -0.1043298 | ... Z9: =('Question 1 - Prices'!AA10-'Question 1 - Prices'!AA9)/'Question 1 - Prices'!AA9 -> 0.11088463 | AC9: =B9-B$62 -> -0.072429997 | AD9: =C9-C$62 -> -0.10196052 | AE9: =D9-D$62 -> -0.00041834449 | AF9: =E9-E$62 -> 0.086250528 | AG9: =F9-F$62 -> -0.02620697 | AH9: =G9-G$62 -> -0.098616683 | AI9: =H9-H$62 -> -0.026827534 | AJ9: =I9-I$62 -> -0.1252949 | ... BA9: =Z9-Z$62 -> 0.072968068 | BC9: CRAI-US | BD9: 0.10883734
A10: 43738 | B10: =('Question 1 - Prices'!C11-'Question 1 - Prices'!C10)/'Question 1 - Prices'!C10 -> -0.13809524 | C10: =('Question 1 - Prices'!D11-'Question 1 - Prices'!D10)/'Question 1 - Prices'!D10 -> 0.11860465 | D10: =('Question 1 - Prices'!E11-'Question 1 - Prices'!E10)/'Question 1 - Prices'!E10 -> -0.040492958 | E10: =('Question 1 - Prices'!F11-'Question 1 - Prices'!F10)/'Question 1 - Prices'!F10 -> 0.13151927 | F10: =('Question 1 - Prices'!G11-'Question 1 - Prices'!G10)/'Question 1 - Prices'!G10 -> 0.053808476 | G10: =('Question 1 - Prices'!H11-'Question 1 - Prices'!H10)/'Question 1 - Prices'!H10 -> 0.032232117 | H10: =('Question 1 - Prices'!I11-'Question 1 - Prices'!I10)/'Question 1 - Prices'!I10 -> 0.074113856 | I10: =('Question 1 - Prices'!J11-'Question 1 - Prices'!J10)/'Question 1 - Prices'!J10 -> 0.079197737 | ... Z10: =('Question 1 - Prices'!AA11-'Question 1 - Prices'!AA10)/'Question 1 - Prices'!AA10 -> -0.060183486 | AC10: =B10-B$62 -> -0.13400808 | AD10: =C10-C$62 -> 0.097840711 | AE10: =D10-D$62 -> -0.042674971 | AF10: =E10-E$62 -> 0.13022356 | AG10: =F10-F$62 -> 0.063464897 | AH10: =G10-G$62 -> 0.022931048 | AI10: =H10-H$62 -> 0.079846073 | AJ10: =I10-I$62 -> 0.05823264 | ... BA10: =Z10-Z$62 -> -0.098100049 | BC10: CHEF-US | BD10: 0.16945624
A11: 43769 | B11: =('Question 1 - Prices'!C12-'Question 1 - Prices'!C11)/'Question 1 - Prices'!C11 -> -0.12596685 | C11: =('Question 1 - Prices'!D12-'Question 1 - Prices'!D11)/'Question 1 - Prices'!D11 -> 0.11018711 | D11: =('Question 1 - Prices'!E12-'Question 1 - Prices'!E11)/'Question 1 - Prices'!E11 -> 0.080366972 | E11: =('Question 1 - Prices'!F12-'Question 1 - Prices'!F11)/'Question 1 - Prices'!F11 -> 0.017034068 | F11: =('Question 1 - Prices'!G12-'Question 1 - Prices'!G11)/'Question 1 - Prices'!G11 -> 0.0087908387 | G11: =('Question 1 - Prices'!H12-'Question 1 - Prices'!H11)/'Question 1 - Prices'!H11 -> 0.013024602 | H11: =('Question 1 - Prices'!I12-'Question 1 - Prices'!I11)/'Question 1 - Prices'!I11 -> -0.20466667 | I11: =('Question 1 - Prices'!J12-'Question 1 - Prices'!J11)/'Question 1 - Prices'!J11 -> 0.17345723 | ... Z11: =('Question 1 - Prices'!AA12-'Question 1 - Prices'!AA11)/'Question 1 - Prices'!AA11 -> -0.016399844 | AC11: =B11-B$62 -> -0.1218797 | AD11: =C11-C$62 -> 0.08942317 | AE11: =D11-D$62 -> 0.07818496 | AF11: =E11-E$62 -> 0.015738357 | AG11: =F11-F$62 -> 0.01844726 | AH11: =G11-G$62 -> 0.0037235323 | AI11: =H11-H$62 -> -0.19893445 | AJ11: =I11-I$62 -> 0.15249213 | ... BA11: =Z11-Z$62 -> -0.054316407 | BC11: SCGPY-US | BD11: 0.077805315
A12: 43798 | B12: =('Question 1 - Prices'!C13-'Question 1 - Prices'!C12)/'Question 1 - Prices'!C12 -> -0.1630847 | C12: =('Question 1 - Prices'!D13-'Question 1 - Prices'!D12)/'Question 1 - Prices'!D12 -> 0.17247191 | D12: =('Question 1 - Prices'!E13-'Question 1 - Prices'!E12)/'Question 1 - Prices'!E12 -> 0.065896739 | E12: =('Question 1 - Prices'!F13-'Question 1 - Prices'!F12)/'Question 1 - Prices'!F12 -> 0.088669951 | F12: =('Question 1 - Prices'!G13-'Question 1 - Prices'!G12)/'Question 1 - Prices'!G12 -> 0.067410103 | G12: =('Question 1 - Prices'!H13-'Question 1 - Prices'!H12)/'Question 1 - Prices'!H12 -> 0.063186813 | H12: =('Question 1 - Prices'!I13-'Question 1 - Prices'!I12)/'Question 1 - Prices'!I12 -> 0.19279128 | I12: =('Question 1 - Prices'!J13-'Question 1 - Prices'!J12)/'Question 1 - Prices'!J12 -> 0.041015228 | ... Z12: =('Question 1 - Prices'!AA13-'Question 1 - Prices'!AA12)/'Question 1 - Prices'!AA12 -> 0.005557761 | AC12: =B12-B$62 -> -0.15899755 | AD12: =C12-C$62 -> 0.15170797 | AE12: =D12-D$62 -> 0.063714726 | AF12: =E12-E$62 -> 0.08737424 | AG12: =F12-F$62 -> 0.077066524 | AH12: =G12-G$62 -> 0.053885743 | AI12: =H12-H$62 -> 0.1985235 | AJ12: =I12-I$62 -> 0.020050131 | ... BA12: =Z12-Z$62 -> -0.032358802 | BC12: KOS-US | BD12: 0.2208126
A13: 43830 | B13: =('Question 1 - Prices'!C14-'Question 1 - Prices'!C13)/'Question 1 - Prices'!C13 -> -0.058912387 | C13: =('Question 1 - Prices'!D14-'Question 1 - Prices'!D13)/'Question 1 - Prices'!D13 -> 0.036575627 | D13: =('Question 1 - Prices'!E14-'Question 1 - Prices'!E13)/'Question 1 - Prices'!E13 -> 0.022307202 | E13: =('Question 1 - Prices'!F14-'Question 1 - Prices'!F13)/'Question 1 - Prices'!F13 -> 0.17647059 | F13: =('Question 1 - Prices'!G14-'Question 1 - Prices'!G13)/'Question 1 - Prices'!G13 -> 0.14010009 | G13: =('Question 1 - Prices'!H14-'Question 1 - Prices'!H13)/'Question 1 - Prices'!H13 -> 0.003255814 | H13: =('Question 1 - Prices'!I14-'Question 1 - Prices'!I13)/'Question 1 - Prices'!I13 -> -0.021433591 | I13: =('Question 1 - Prices'!J14-'Question 1 - Prices'!J13)/'Question 1 - Prices'!J13 -> 0.062414667 | ... Z13: =('Question 1 - Prices'!AA14-'Question 1 - Prices'!AA13)/'Question 1 - Prices'!AA13 -> 0.0031583103 | AC13: =B13-B$62 -> -0.054825233 | AD13: =C13-C$62 -> 0.015811687 | AE13: =D13-D$62 -> 0.020125189 | AF13: =E13-E$62 -> 0.17517488 | AG13: =F13-F$62 -> 0.14975651 | AH13: =G13-G$62 -> -0.0060452558 | AI13: =H13-H$62 -> -0.015701374 | AJ13: =I13-I$62 -> 0.04144957 | ... BA13: =Z13-Z$62 -> -0.034758253 | BC13: DIISY-US | BD13: 0.11417749
A14: 43861 | B14: =('Question 1 - Prices'!C15-'Question 1 - Prices'!C14)/'Question 1 - Prices'!C14 -> -0.12359551 | C14: =('Question 1 - Prices'!D15-'Question 1 - Prices'!D14)/'Question 1 - Prices'!D14 -> 0.026194145 | D14: =('Question 1 - Prices'!E15-'Question 1 - Prices'!E14)/'Question 1 - Prices'!E14 -> -0.071150249 | E14: =('Question 1 - Prices'!F15-'Question 1 - Prices'!F14)/'Question 1 - Prices'!F14 -> -0.096153846 | F14: =('Question 1 - Prices'!G15-'Question 1 - Prices'!G14)/'Question 1 - Prices'!G14 -> -0.11490027 | G14: =('Question 1 - Prices'!H15-'Question 1 - Prices'!H14)/'Question 1 - Prices'!H14 -> 0.072528718 | H14: =('Question 1 - Prices'!I15-'Question 1 - Prices'!I14)/'Question 1 - Prices'!I14 -> -0.33788151 | I14: =('Question 1 - Prices'!J15-'Question 1 - Prices'!J14)/'Question 1 - Prices'!J14 -> -0.021846888 | ... Z14: =('Question 1 - Prices'!AA15-'Question 1 - Prices'!AA14)/'Question 1 - Prices'!AA14 -> 0.27902401 | AC14: =B14-B$62 -> -0.11950835 | AD14: =C14-C$62 -> 0.0054302051 | AE14: =D14-D$62 -> -0.073332262 | AF14: =E14-E$62 -> -0.097449557 | AG14: =F14-F$62 -> -0.10524385 | AH14: =G14-G$62 -> 0.063227648 | AI14: =H14-H$62 -> -0.33214929 | AJ14: =I14-I$62 -> -0.042811986 | ... BA14: =Z14-Z$62 -> 0.24110744 | BC14: TSLA-US | BD14: 0.21227491
... A26: 44225 | B26: =('Question 1 - Prices'!C27-'Question 1 - Prices'!C26)/'Question 1 - Prices'!C26 -> 0.16568047 | C26: =('Question 1 - Prices'!D27-'Question 1 - Prices'!D26)/'Question 1 - Prices'!D26 -> -0.033557047 | D26: =('Question 1 - Prices'!E27-'Question 1 - Prices'!E26)/'Question 1 - Prices'!E26 -> -0.058141103 | E26: =('Question 1 - Prices'!F27-'Question 1 - Prices'!F26)/'Question 1 - Prices'!F26 -> -0.040636042 | F26: =('Question 1 - Prices'!G27-'Question 1 - Prices'!G26)/'Question 1 - Prices'!G26 -> -0.053566295 | G26: =('Question 1 - Prices'!H27-'Question 1 - Prices'!H26)/'Question 1 - Prices'!H26 -> -0.0041664913 | H26: =('Question 1 - Prices'!I27-'Question 1 - Prices'!I26)/'Question 1 - Prices'!I26 -> -0.039011146 | I26: =('Question 1 - Prices'!J27-'Question 1 - Prices'!J26)/'Question 1 - Prices'!J26 -> 0.044767328 | ... Z26: =('Question 1 - Prices'!AA27-'Question 1 - Prices'!AA26)/'Question 1 - Prices'!AA26 -> -0.041427827 | AC26: =B26-B$62 -> 0.16976763 | AD26: =C26-C$62 -> -0.054320987 | AE26: =D26-D$62 -> -0.060323116 | AF26: =E26-E$62 -> -0.041931753 | AG26: =F26-F$62 -> -0.043909874 | AH26: =G26-G$62 -> -0.013467561 | AI26: =H26-H$62 -> -0.033278929 | AJ26: =I26-I$62 -> 0.02380223 | ... BA26: =Z26-Z$62 -> -0.07934439 | BC26: AGYS-US | BD26: 0.14413002
A27: 44253 | B27: =('Question 1 - Prices'!C28-'Question 1 - Prices'!C27)/'Question 1 - Prices'!C27 -> 0.3358714 | C27: =('Question 1 - Prices'!D28-'Question 1 - Prices'!D27)/'Question 1 - Prices'!D27 -> 0.016666667 | D27: =('Question 1 - Prices'!E28-'Question 1 - Prices'!E27)/'Question 1 - Prices'!E27 -> 0.038097966 | E27: =('Question 1 - Prices'!F28-'Question 1 - Prices'!F27)/'Question 1 - Prices'!F27 -> -0.019521179 | F27: =('Question 1 - Prices'!G28-'Question 1 - Prices'!G27)/'Question 1 - Prices'!G27 -> 0.085487681 | G27: =('Question 1 - Prices'!H28-'Question 1 - Prices'!H27)/'Question 1 - Prices'!H27 -> 0.065252303 | H27: =('Question 1 - Prices'!I28-'Question 1 - Prices'!I27)/'Question 1 - Prices'!I27 -> -0.039256506 | I27: =('Question 1 - Prices'!J28-'Question 1 - Prices'!J27)/'Question 1 - Prices'!J27 -> 0.036835181 | ... Z27: =('Question 1 - Prices'!AA28-'Question 1 - Prices'!AA27)/'Question 1 - Prices'!AA27 -> 0.61973362 | AC27: =B27-B$62 -> 0.33995856 | AD27: =C27-C$62 -> -0.0040972731 | AE27: =D27-D$62 -> 0.035915953 | AF27: =E27-E$62 -> -0.02081689 | AG27: =F27-F$62 -> 0.095144102 | AH27: =G27-G$62 -> 0.055951234 | AI27: =H27-H$62 -> -0.033524289 | AJ27: =I27-I$62 -> 0.015870084 | ... BA27: =Z27-Z$62 -> 0.58181706
A28: 44286 | B28: =('Question 1 - Prices'!C29-'Question 1 - Prices'!C28)/'Question 1 - Prices'!C28 -> -0.16212793 | C28: =('Question 1 - Prices'!D29-'Question 1 - Prices'!D28)/'Question 1 - Prices'!D28 -> -0.15163934 | D28: =('Question 1 - Prices'!E29-'Question 1 - Prices'!E28)/'Question 1 - Prices'!E28 -> -0.03352649 | E28: =('Question 1 - Prices'!F29-'Question 1 - Prices'!F28)/'Question 1 - Prices'!F28 -> -0.025544703 | F28: =('Question 1 - Prices'!G29-'Question 1 - Prices'!G28)/'Question 1 - Prices'!G28 -> 0.010788795 | G28: =('Question 1 - Prices'!H29-'Question 1 - Prices'!H28)/'Question 1 - Prices'!H28 -> 0.065301912 | H28: =('Question 1 - Prices'!I29-'Question 1 - Prices'!I28)/'Question 1 - Prices'!I28 -> -0.078006501 | I28: =('Question 1 - Prices'!J29-'Question 1 - Prices'!J28)/'Question 1 - Prices'!J28 -> 0.35290919 | ... Z28: =('Question 1 - Prices'!AA29-'Question 1 - Prices'!AA28)/'Question 1 - Prices'!AA28 -> -0.19516697 | AC28: =B28-B$62 -> -0.15804078 | AD28: =C28-C$62 -> -0.17240328 | AE28: =D28-D$62 -> -0.035708503 | AF28: =E28-E$62 -> -0.026840414 | AG28: =F28-F$62 -> 0.020445215 | AH28: =G28-G$62 -> 0.056000843 | AI28: =H28-H$62 -> -0.072274284 | AJ28: =I28-I$62 -> 0.33194409 | ... BA28: =Z28-Z$62 -> -0.23308354
A29: 44316 | B29: =('Question 1 - Prices'!C30-'Question 1 - Prices'!C29)/'Question 1 - Prices'!C29 -> -0.15570673 | C29: =('Question 1 - Prices'!D30-'Question 1 - Prices'!D29)/'Question 1 - Prices'!D29 -> 0.0064412238 | D29: =('Question 1 - Prices'!E30-'Question 1 - Prices'!E29)/'Question 1 - Prices'!E29 -> 0.018891268 | E29: =('Question 1 - Prices'!F30-'Question 1 - Prices'!F29)/'Question 1 - Prices'!F29 -> 0.10639938 | F29: =('Question 1 - Prices'!G30-'Question 1 - Prices'!G29)/'Question 1 - Prices'!G29 -> -0.080190711 | G29: =('Question 1 - Prices'!H30-'Question 1 - Prices'!H29)/'Question 1 - Prices'!H29 -> 0.039922538 | H29: =('Question 1 - Prices'!I30-'Question 1 - Prices'!I29)/'Question 1 - Prices'!I29 -> 0.18381736 | I29: =('Question 1 - Prices'!J30-'Question 1 - Prices'!J29)/'Question 1 - Prices'!J29 -> 0.075294748 | ... Z29: =('Question 1 - Prices'!AA30-'Question 1 - Prices'!AA29)/'Question 1 - Prices'!AA29 -> 0.051084237 | AC29: =B29-B$62 -> -0.15161957 | AD29: =C29-C$62 -> -0.014322716 | AE29: =D29-D$62 -> 0.016709255 | AF29: =E29-E$62 -> 0.10510367 | AG29: =F29-F$62 -> -0.07053429 | AH29: =G29-G$62 -> 0.030621469 | AI29: =H29-H$62 -> 0.18954957 | AJ29: =I29-I$62 -> 0.054329651 | ... BA29: =Z29-Z$62 -> 0.013167674
A30: 44344 | B30: =('Question 1 - Prices'!C31-'Question 1 - Prices'!C30)/'Question 1 - Prices'!C30 -> -0.12712623 | C30: =('Question 1 - Prices'!D31-'Question 1 - Prices'!D30)/'Question 1 - Prices'!D30 -> 0.1792 | D30: =('Question 1 - Prices'!E31-'Question 1 - Prices'!E30)/'Question 1 - Prices'!E30 -> -0.0053241173 | E30: =('Question 1 - Prices'!F31-'Question 1 - Prices'!F30)/'Question 1 - Prices'!F30 -> -0.024390244 | F30: =('Question 1 - Prices'!G31-'Question 1 - Prices'!G30)/'Question 1 - Prices'!G30 -> 0.034076848 | G30: =('Question 1 - Prices'!H31-'Question 1 - Prices'!H30)/'Question 1 - Prices'!H30 -> 0.0059447071 | H30: =('Question 1 - Prices'!I31-'Question 1 - Prices'!I30)/'Question 1 - Prices'!I30 -> 0.05643789 | I30: =('Question 1 - Prices'!J31-'Question 1 - Prices'!J30)/'Question 1 - Prices'!J30 -> 0.019935211 | ... Z30: =('Question 1 - Prices'!AA31-'Question 1 - Prices'!AA30)/'Question 1 - Prices'!AA30 -> 0.0075381869 | AC30: =B30-B$62 -> -0.12303908 | AD30: =C30-C$62 -> 0.15843606 | AE30: =D30-D$62 -> -0.0075061302 | AF30: =E30-E$62 -> -0.025685955 | AG30: =F30-F$62 -> 0.043733269 | AH30: =G30-G$62 -> -0.0033563626 | AI30: =H30-H$62 -> 0.062170107 | AJ30: =I30-I$62 -> -0.001029887 | ... BA30: =Z30-Z$62 -> -0.030378376
A31: 44377 | B31: =('Question 1 - Prices'!C32-'Question 1 - Prices'!C31)/'Question 1 - Prices'!C31 -> 0.097435897 | C31: =('Question 1 - Prices'!D32-'Question 1 - Prices'!D31)/'Question 1 - Prices'!D31 -> -0.010854817 | D31: =('Question 1 - Prices'!E32-'Question 1 - Prices'!E31)/'Question 1 - Prices'!E31 -> 0.088834632 | E31: =('Question 1 - Prices'!F32-'Question 1 - Prices'!F31)/'Question 1 - Prices'!F31 -> -0.028571429 | F31: =('Question 1 - Prices'!G32-'Question 1 - Prices'!G31)/'Question 1 - Prices'!G31 -> -0.14216415 | G31: =('Question 1 - Prices'!H32-'Question 1 - Prices'!H31)/'Question 1 - Prices'!H31 -> -0.055144179 | H31: =('Question 1 - Prices'!I32-'Question 1 - Prices'!I31)/'Question 1 - Prices'!I31 -> -0.0080536913 | I31: =('Question 1 - Prices'!J32-'Question 1 - Prices'!J31)/'Question 1 - Prices'!J31 -> 0.04568776 | ... Z31: =('Question 1 - Prices'!AA32-'Question 1 - Prices'!AA31)/'Question 1 - Prices'!AA31 -> 0.1197086 | AC31: =B31-B$62 -> 0.10152305 | AD31: =C31-C$62 -> -0.031618757 | AE31: =D31-D$62 -> 0.086652619 | AF31: =E31-E$62 -> -0.02986714 | AG31: =F31-F$62 -> -0.13250773 | AH31: =G31-G$62 -> -0.064445249 | AI31: =H31-H$62 -> -0.0023214743 | AJ31: =I31-I$62 -> 0.024722662 | ... BA31: =Z31-Z$62 -> 0.081792041
A32: 44407 | B32: =('Question 1 - Prices'!C33-'Question 1 - Prices'!C32)/'Question 1 - Prices'!C32 -> -0.098130841 | C32: =('Question 1 - Prices'!D33-'Question 1 - Prices'!D32)/'Question 1 - Prices'!D32 -> -0.10699588 | D32: =('Question 1 - Prices'!E33-'Question 1 - Prices'!E32)/'Question 1 - Prices'!E32 -> -0.12005175 | E32: =('Question 1 - Prices'!F33-'Question 1 - Prices'!F32)/'Question 1 - Prices'!F32 -> 0.042647059 | F32: =('Question 1 - Prices'!G33-'Question 1 - Prices'!G32)/'Question 1 - Prices'!G32 -> -0.098921813 | G32: =('Question 1 - Prices'!H33-'Question 1 - Prices'!H32)/'Question 1 - Prices'!H32 -> -0.028559587 | H32: =('Question 1 - Prices'!I33-'Question 1 - Prices'!I32)/'Question 1 - Prices'!I32 -> -0.092286874 | I32: =('Question 1 - Prices'!J33-'Question 1 - Prices'!J32)/'Question 1 - Prices'!J32 -> 0.0015186916 | ... Z32: =('Question 1 - Prices'!AA33-'Question 1 - Prices'!AA32)/'Question 1 - Prices'!AA32 -> -0.023034992 | AC32: =B32-B$62 -> -0.094043688 | AD32: =C32-C$62 -> -0.12775982 | AE32: =D32-D$62 -> -0.12223376 | AF32: =E32-E$62 -> 0.041351348 | AG32: =F32-F$62 -> -0.089265392 | AH32: =G32-G$62 -> -0.037860657 | AI32: =H32-H$62 -> -0.086554657 | AJ32: =I32-I$62 -> -0.019446406 | ... BA32: =Z32-Z$62 -> -0.060951555
A33: 44439 | B33: =('Question 1 - Prices'!C34-'Question 1 - Prices'!C33)/'Question 1 - Prices'!C33 -> 0.0010362694 | C33: =('Question 1 - Prices'!D34-'Question 1 - Prices'!D33)/'Question 1 - Prices'!D33 -> 0.21658986 | D33: =('Question 1 - Prices'!E34-'Question 1 - Prices'!E33)/'Question 1 - Prices'!E33 -> 0.082573753 | E33: =('Question 1 - Prices'!F34-'Question 1 - Prices'!F33)/'Question 1 - Prices'!F33 -> 0.16361072 | F33: =('Question 1 - Prices'!G34-'Question 1 - Prices'!G33)/'Question 1 - Prices'!G33 -> 0.13237386 | G33: =('Question 1 - Prices'!H34-'Question 1 - Prices'!H33)/'Question 1 - Prices'!H33 -> -0.016638871 | H33: =('Question 1 - Prices'!I34-'Question 1 - Prices'!I33)/'Question 1 - Prices'!I33 -> -0.091383423 | I33: =('Question 1 - Prices'!J34-'Question 1 - Prices'!J33)/'Question 1 - Prices'!J33 -> 0.084684475 | ... Z33: =('Question 1 - Prices'!AA34-'Question 1 - Prices'!AA33)/'Question 1 - Prices'!AA33 -> 0.022858171 | AC33: =B33-B$62 -> 0.0051234228 | AD33: =C33-C$62 -> 0.19582592 | AE33: =D33-D$62 -> 0.08039174 | AF33: =E33-E$62 -> 0.16231501 | AG33: =F33-F$62 -> 0.14203028 | AH33: =G33-G$62 -> -0.02593994 | AI33: =H33-H$62 -> -0.085651206 | AJ33: =I33-I$62 -> 0.063719377 | ... BA33: =Z33-Z$62 -> -0.015058392
A34: 44469 | B34: =('Question 1 - Prices'!C35-'Question 1 - Prices'!C34)/'Question 1 - Prices'!C34 -> -0.13664596 | C34: =('Question 1 - Prices'!D35-'Question 1 - Prices'!D34)/'Question 1 - Prices'!D34 -> 0.18939394 | D34: =('Question 1 - Prices'!E35-'Question 1 - Prices'!E34)/'Question 1 - Prices'!E34 -> -0.018514327 | E34: =('Question 1 - Prices'!F35-'Question 1 - Prices'!F34)/'Question 1 - Prices'!F34 -> -0.05030303 | F34: =('Question 1 - Prices'!G35-'Question 1 - Prices'!G34)/'Question 1 - Prices'!G34 -> -0.0033252051 | G34: =('Question 1 - Prices'!H35-'Question 1 - Prices'!H34)/'Question 1 - Prices'!H34 -> -0.056361915 | H34: =('Question 1 - Prices'!I35-'Question 1 - Prices'!I34)/'Question 1 - Prices'!I34 -> 0.032813782 | I34: =('Question 1 - Prices'!J35-'Question 1 - Prices'!J34)/'Question 1 - Prices'!J34 -> 0.068286913 | ... Z34: =('Question 1 - Prices'!AA35-'Question 1 - Prices'!AA34)/'Question 1 - Prices'!AA34 -> -0.07865564 | AC34: =B34-B$62 -> -0.13255881 | AD34: =C34-C$62 -> 0.16863 | AE34: =D34-D$62 -> -0.02069634 | AF34: =E34-E$62 -> -0.051598741 | AG34: =F34-F$62 -> 0.0063312159 | AH34: =G34-G$62 -> -0.065662985 | AI34: =H34-H$62 -> 0.038545999 | AJ34: =I34-I$62 -> 0.047321815 | ... BA34: =Z34-Z$62 -> -0.1165722
A35: 44498 | B35: =('Question 1 - Prices'!C36-'Question 1 - Prices'!C35)/'Question 1 - Prices'!C35 -> -0.092326139 | C35: =('Question 1 - Prices'!D36-'Question 1 - Prices'!D35)/'Question 1 - Prices'!D35 -> -0.016985138 | D35: =('Question 1 - Prices'!E36-'Question 1 - Prices'!E35)/'Question 1 - Prices'!E35 -> 0.13541186 | E35: =('Question 1 - Prices'!F36-'Question 1 - Prices'!F35)/'Question 1 - Prices'!F35 -> -0.017230377 | F35: =('Question 1 - Prices'!G36-'Question 1 - Prices'!G35)/'Question 1 - Prices'!G35 -> -0.077884045 | G35: =('Question 1 - Prices'!H36-'Question 1 - Prices'!H35)/'Question 1 - Prices'!H35 -> 0.22486938 | H35: =('Question 1 - Prices'!I36-'Question 1 - Prices'!I35)/'Question 1 - Prices'!I35 -> -0.012073074 | I35: =('Question 1 - Prices'!J36-'Question 1 - Prices'!J35)/'Question 1 - Prices'!J35 -> 0.10549628 | ... Z35: =('Question 1 - Prices'!AA36-'Question 1 - Prices'!AA35)/'Question 1 - Prices'!AA35 -> -0.088617265 | AC35: =B35-B$62 -> -0.088238986 | AD35: =C35-C$62 -> -0.037749078 | AE35: =D35-D$62 -> 0.13322985 | AF35: =E35-E$62 -> -0.018526088 | AG35: =F35-F$62 -> -0.068227624 | AH35: =G35-G$62 -> 0.21556831 | AI35: =H35-H$62 -> -0.0063408569 | AJ35: =I35-I$62 -> 0.084531178 | ... BA35: =Z35-Z$62 -> -0.12653383
A36: 44530 | B36: =('Question 1 - Prices'!C37-'Question 1 - Prices'!C36)/'Question 1 - Prices'!C36 -> -0.12417437 | C36: =('Question 1 - Prices'!D37-'Question 1 - Prices'!D36)/'Question 1 - Prices'!D36 -> -0.52591793 | D36: =('Question 1 - Prices'!E37-'Question 1 - Prices'!E36)/'Question 1 - Prices'!E36 -> -0.00028434479 | E36: =('Question 1 - Prices'!F37-'Question 1 - Prices'!F36)/'Question 1 - Prices'!F36 -> -0.068181818 | F36: =('Question 1 - Prices'!G37-'Question 1 - Prices'!G36)/'Question 1 - Prices'!G36 -> -0.085949749 | G36: =('Question 1 - Prices'!H37-'Question 1 - Prices'!H36)/'Question 1 - Prices'!H36 -> -0.09479611 | H36: =('Question 1 - Prices'!I37-'Question 1 - Prices'!I36)/'Question 1 - Prices'!I36 -> 0.13394436 | I36: =('Question 1 - Prices'!J37-'Question 1 - Prices'!J36)/'Question 1 - Prices'!J36 -> -0.16162812 | ... Z36: =('Question 1 - Prices'!AA37-'Question 1 - Prices'!AA36)/'Question 1 - Prices'!AA36 -> -0.087384744 | AC36: =B36-B$62 -> -0.12008722 | AD36: =C36-C$62 -> -0.54668187 | AE36: =D36-D$62 -> -0.0024663577 | AF36: =E36-E$62 -> -0.069477529 | AG36: =F36-F$62 -> -0.076293328 | AH36: =G36-G$62 -> -0.10409718 | AI36: =H36-H$62 -> 0.13967658 | AJ36: =I36-I$62 -> -0.18259322 | ... BA36: =Z36-Z$62 -> -0.12530131
A37: 44561 | B37: =('Question 1 - Prices'!C38-'Question 1 - Prices'!C37)/'Question 1 - Prices'!C37 -> -0.031674208 | C37: =('Question 1 - Prices'!D38-'Question 1 - Prices'!D37)/'Question 1 - Prices'!D37 -> 0.0022779043 | D37: =('Question 1 - Prices'!E38-'Question 1 - Prices'!E37)/'Question 1 - Prices'!E37 -> -0.038234936 | E37: =('Question 1 - Prices'!F38-'Question 1 - Prices'!F37)/'Question 1 - Prices'!F37 -> 0.017421603 | F37: =('Question 1 - Prices'!G38-'Question 1 - Prices'!G37)/'Question 1 - Prices'!G37 -> 0.098649778 | G37: =('Question 1 - Prices'!H38-'Question 1 - Prices'!H37)/'Question 1 - Prices'!H37 -> 0.1222905 | H37: =('Question 1 - Prices'!I38-'Question 1 - Prices'!I37)/'Question 1 - Prices'!I37 -> 0.033182076 | I37: =('Question 1 - Prices'!J38-'Question 1 - Prices'!J37)/'Question 1 - Prices'!J37 -> 0.014011079 | ... Z37: =('Question 1 - Prices'!AA38-'Question 1 - Prices'!AA37)/'Question 1 - Prices'!AA37 -> 0.020895522 | AC37: =B37-B$62 -> -0.027587055 | AD37: =C37-C$62 -> -0.018486035 | AE37: =D37-D$62 -> -0.040416949 | AF37: =E37-E$62 -> 0.016125892 | AG37: =F37-F$62 -> 0.1083062 | AH37: =G37-G$62 -> 0.11298943 | AI37: =H37-H$62 -> 0.038914293 | AJ37: =I37-I$62 -> -0.006954019 | ... BA37: =Z37-Z$62 -> -0.017021041
A38: 44592 | B38: =('Question 1 - Prices'!C39-'Question 1 - Prices'!C38)/'Question 1 - Prices'!C38 -> -0.19158879 | C38: =('Question 1 - Prices'!D39-'Question 1 - Prices'!D38)/'Question 1 - Prices'!D38 -> 0.056818182 | D38: =('Question 1 - Prices'!E39-'Question 1 - Prices'!E38)/'Question 1 - Prices'!E38 -> 0.11888466 | E38: =('Question 1 - Prices'!F39-'Question 1 - Prices'!F38)/'Question 1 - Prices'!F38 -> -0.1369863 | F38: =('Question 1 - Prices'!G39-'Question 1 - Prices'!G38)/'Question 1 - Prices'!G38 -> 0.055004003 | G38: =('Question 1 - Prices'!H39-'Question 1 - Prices'!H38)/'Question 1 - Prices'!H38 -> -0.086392798 | H38: =('Question 1 - Prices'!I39-'Question 1 - Prices'!I38)/'Question 1 - Prices'!I38 -> -0.23579467 | I38: =('Question 1 - Prices'!J39-'Question 1 - Prices'!J38)/'Question 1 - Prices'!J38 -> -0.088903171 | ... Z38: =('Question 1 - Prices'!AA39-'Question 1 - Prices'!AA38)/'Question 1 - Prices'!AA38 -> -0.14394962 | AC38: =B38-B$62 -> -0.18750163 | AD38: =C38-C$62 -> 0.036054242 | AE38: =D38-D$62 -> 0.11670265 | AF38: =E38-E$62 -> -0.13828201 | AG38: =F38-F$62 -> 0.064660424 | AH38: =G38-G$62 -> -0.095693868 | AI38: =H38-H$62 -> -0.23006246 | AJ38: =I38-I$62 -> -0.10986827 | ... BA38: =Z38-Z$62 -> -0.18186618
